Workbook
Name _C1: Crises!$P$5:$X$5
Name _C1Enabled: Crises!$P$7:$X$7
Name _C1Prepared: Crises!$P$8:$X$8
Name _C1Show: Crises!$P$6:$X$6
Name _C1ShowCrisisCard: Crises!$P$9:$X$9
Name _C1Year: Crises!$P$4:$X$4
Name _C2: Crises!$AD$5:$AL$5
Name _C2Enabled: Crises!$AD$7:$AL$7
Name _C2Prepared: Crises!$AD$8:$AL$8
Name _C2Show: Crises!$AD$6:$AL$6
Name _C2ShowCrisisCard: Crises!$AD$9:$AL$9
Name _C2Year: Crises!$AD$4:$AL$4
Name _C3: Crises!$AR$5:$AZ$5
Name _C3Enabled: Crises!$AR$7:$AZ$7
Name _C3Prepared: Crises!$AR$8:$AZ$8
Name _C3Show: Crises!$AR$6:$AZ$6
Name _C3ShowCrisisCard: Crises!$AR$9:$AZ$9
Name _C3Year: Crises!$AR$4:$AZ$4
Name _C4: Crises!$BF$5:$BN$5
Name _C4Enabled: Crises!$BF$7:$BN$7
Name _C4Prepared: Crises!$BF$8:$BN$8
Name _C4Show: Crises!$BF$6:$BN$6
Name _C4ShowCrisisCard: Crises!$BF$9:$BN$9
Name _C4Year: Crises!$BF$4:$BN$4
Name _C5: Crises!$BT$5:$CB$5
Name _C5Enabled: Crises!$BT$7:$CB$7
Name _C5Prepared: Crises!$BT$8:$CB$8
Name _C5Show: Crises!$BT$6:$CB$6
Name _C5ShowCrisisCard: Crises!$BT$9:$CB$9
Name _C5Year: Crises!$BT$4:$CB$4
Name _C6: Crises!$CH$5:$CP$5
Name _C6Enabled: Crises!$CH$7:$CP$7
Name _C6Prepared: Crises!$CH$8:$CP$8
Name _C6Show: Crises!$CH$6:$CP$6
Name _C6ShowCrisisCard: Crises!$CH$9:$CP$9
Name _C6Year: Crises!$CH$4:$CP$4
Name _C7: Crises!$CV$5:$DD$5
Name _C7Enabled: Crises!$CV$7:$DD$7
Name _C7Prepared: Crises!$CV$8:$DD$8
Name _C7Show: Crises!$CV$6:$DD$6
Name _C7ShowCrisisCard: Crises!$CV$9:$DD$9
Name _C7Year: Crises!$CV$4:$DD$4
Name _C8: Crises!$DJ$5:$DR$5
Name _C8Enabled: Crises!$DJ$7:$DR$7
Name _C8Prepared: Crises!$DJ$8:$DR$8
Name _C8Show: Crises!$DJ$6:$DR$6
Name _C8ShowCrisisCard: Crises!$DJ$9:$DR$9
Name _C8Year: Crises!$DJ$4:$DR$4
Name Accountability: Results!$B$69:$J$69
Name AIContributionToGDP: Results!$B$73:$J$73
Name AIContributionToGDPPercOfTargetAchieved: 'Result Targets'!$B$73:$J$73
Name AIContributionToGDPTarget: 'Result Targets'!$B$5:$J$5
Name AIFDIStock: Results!$B$74:$J$74
Name AIFDIStockPercOfTargetAchieved: 'Result Targets'!$B$74:$J$74
Name AIFDIStockTarget: 'Result Targets'!$B$6:$J$6
Name AIFeedbackEnabled: 'Project Variables'!$B$7
Name AILiteracy: Results!$B$102:$J$102
Name AILiteracyPercOfTargetAchieved: 'Result Targets'!$B$102:$J$102
Name AILiteracyTarget: 'Result Targets'!$B$31:$J$31
Name AutonomousSystemsSafteyIndex: Results!$B$94:$J$94

Sheet Project Variables
A1: settingsID | B1: 0
A2: ReadVault | B2: 0
A3: NumYears | B3: 5
A4: GameOver | B4: =IF(Step=NumYears,1,0) -> 0
A6: Misc
A7: AIFeedbackEnabled | B7: 0
A8: IsMultiplayer | B8: 0
A9: SliderReasoningEnabled | B9: 0
A10: TeamName
A12: Enabled Ministries
A13: EcEnabled | B13: 1
A14: EnvEnabled | B14: 1
A15: DefEnabled | B15: 1
A16: EduEnabled | B16: 1
A17: FacEcEnabled | B17: 1
A18: FacEnvEnabled | B18: 1
A19: FacDefEnabled | B19: 1
A20: FacEduEnabled | B20: 1
A21: FacAllowMinistryChoice | B21: 1
A22: MinistriesConfirmed | B22: 0
A24: Role Selection
A25: RoleUser0 | B25: 0
A26: RoleUser1 | B26: 0
A27: RoleUser2 | B27: 0
A28: RoleUser3 | B28: 0
A29: RoleUser4 | B29: 0
A30: RolesConfirmed | B30: 0
D31: Position | E31: 1 | F31: 2 | G31: 3 | H31: 4 | I31: 5 | J31: 6
A32: Values | D32: Weight | E32: 0.25 | F32: 0.25 | G32: 0.15 | H32: 0.15 | I32: 0.1 | J32: 0.1
A33: Value1Position | B33: 1 | D33: Growth & Welbeing | E33: =_xlfn.XLOOKUP(Value1Position,$E$31:$J$31,$E$32:$J$32) -> 0.25
A34: Value2Position | B34: 2 | D34: Human Rights | E34: =_xlfn.XLOOKUP(Value2Position,$E$31:$J$31,$E$32:$J$32) -> 0.25
A35: Value3Position | B35: 3 | D35: Privacy & Data Protection | E35: =_xlfn.XLOOKUP(Value3Position,$E$31:$J$31,$E$32:$J$32) -> 0.15
A36: Value4Position | B36: 4 | D36: Transparency | E36: =_xlfn.XLOOKUP(Value4Position,$E$31:$J$31,$E$32:$J$32) -> 0.15
A37: Value5Position | B37: 5 | D37: Security & Safety | E37: =_xlfn.XLOOKUP(Value5Position,$E$31:$J$31,$E$32:$J$32) -> 0.1
A38: Value6Position | B38: 6 | D38: Accountability | E38: =_xlfn.XLOOKUP(Value6Position,$E$31:$J$31,$E$32:$J$32) -> 0.1
A39: ValuesConfirmed | B39: 0
A41: RoleUser0Value1Position | B41: 1 | D41: Rows Reference
A42: RoleUser0Value2Position | B42: 2 | D42: Governance
A43: RoleUser0Value3Position | B43: 3 | D43: GrowthWellBeing
A44: RoleUser0Value4Position | B44: 4 | D44: HumanRights
...

Sheet Target Settings
A1: FacilSetsTargets | B1: 0
A3: Economy | E3: Defaults
A4: F_AIContributionToGDPTarget | B4: =E4 -> 12 | E4: 12
A5: F_AIFDIStockTarget | B5: =E5 -> 2.5 | E5: 2.5
A6: F_NetJobsFromAITarget | B6: =E6 -> 500000 | E6: 500000
A9: Environment
A10: F_RenewableEnergyFactorTarget | B10: =E10 -> 40 | E10: 40
A11: F_CircularityIndexTarget | B11: =E11 -> 60 | E11: 60
A12: F_EcosystemIntegrityIndexTarget | B12: =E12 -> 60 | E12: 60
A15: Defense
A16: F_CybersecurityIndexTarget | B16: =E16 -> 65 | E16: 65
A17: F_AutonomousSystemsSafteyIndexTarget | B17: =E17 -> 75 | E17: 75
A18: F_MilitaryTechnologyTradeBalanceTarget | B18: =E18 -> 2000000000 | E18: 2000000000
A21: Education & Innovation
A22: F_AILiteracyTarget | B22: =E22 -> 60 | E22: 60
A23: F_InnovationIndexTarget | B23: =E23 -> 60 | E23: 60
A24: F_InstitutionalAdoptionRateTarget | B24: =E24 -> 65 | E24: 65

Sheet Results
A1: Public Policy Simulation: AI Governance
A3: Step | B3: 0
A5: Time | B5: 0 | C5: 1 | D5: 2 | E5: 3 | F5: 4 | G5: 5 | H5: 6 | I5: 7 | J5: 8
A6: Year | B6: 1 | C6: 2 | D6: 3 | E6: 4 | F6: 5 | G6: 6 | H6: 7 | I6: 8 | J6: 9
A63: Governance
A64: GrowthWellBeing | B64: 50 | C64: =$B64+'Economy Ministry'!C64+'Environment Ministry'!C64+'Defence Ministry'!C64+'Education Ministry'!C64+Crises!C64+'Breaking News'!C64+Opportunities!C64 -> 50 | D64: =$B64+'Economy Ministry'!D64+'Environment Ministry'!D64+'Defence Ministry'!D64+'Education Ministry'!D64+Crises!D64+'Breaking News'!D64+Opportunities!D64 -> 48.4 | E64: =$B64+'Economy Ministry'!E64+'Environment Ministry'!E64+'Defence Ministry'!E64+'Education Ministry'!E64+Crises!E64+'Breaking News'!E64+Opportunities!E64 -> 48.4 | F64: =$B64+'Economy Ministry'!F64+'Environment Ministry'!F64+'Defence Ministry'!F64+'Education Ministry'!F64+Crises!F64+'Breaking News'!F64+Opportunities!F64 -> 48.4 | G64: =$B64+'Economy Ministry'!G64+'Environment Ministry'!G64+'Defence Ministry'!G64+'Education Ministry'!G64+Crises!G64+'Breaking News'!G64+Opportunities!G64 -> 48.4 | H64: =$B64+'Economy Ministry'!H64+'Environment Ministry'!H64+'Defence Ministry'!H64+'Education Ministry'!H64+Crises!H64+'Breaking News'!H64+Opportunities!H64 -> 48.4 | I64: =$B64+'Economy Ministry'!I64+'Environment Ministry'!I64+'Defence Ministry'!I64+'Education Ministry'!I64+Crises!I64+'Breaking News'!I64+Opportunities!I64 -> 48.4 | J64: =$B64+'Economy Ministry'!J64+'Environment Ministry'!J64+'Defence Ministry'!J64+'Education Ministry'!J64+Crises!J64+'Breaking News'!J64+Opportunities!J64 -> 48.4
A65: HumanRights | B65: 55 | C65: =$B65+'Economy Ministry'!C65+'Environment Ministry'!C65+'Defence Ministry'!C65+'Education Ministry'!C65+Crises!C65+'Breaking News'!C65+Opportunities!C65 -> 55 | D65: =$B65+'Economy Ministry'!D65+'Environment Ministry'!D65+'Defence Ministry'!D65+'Education Ministry'!D65+Crises!D65+'Breaking News'!D65+Opportunities!D65 -> 55 | E65: =$B65+'Economy Ministry'!E65+'Environment Ministry'!E65+'Defence Ministry'!E65+'Education Ministry'!E65+Crises!E65+'Breaking News'!E65+Opportunities!E65 -> 52.6 | F65: =$B65+'Economy Ministry'!F65+'Environment Ministry'!F65+'Defence Ministry'!F65+'Education Ministry'!F65+Crises!F65+'Breaking News'!F65+Opportunities!F65 -> 52.6 | G65: =$B65+'Economy Ministry'!G65+'Environment Ministry'!G65+'Defence Ministry'!G65+'Education Ministry'!G65+Crises!G65+'Breaking News'!G65+Opportunities!G65 -> 52.6 | H65: =$B65+'Economy Ministry'!H65+'Environment Ministry'!H65+'Defence Ministry'!H65+'Education Ministry'!H65+Crises!H65+'Breaking News'!H65+Opportunities!H65 -> 52.6 | I65: =$B65+'Economy Ministry'!I65+'Environment Ministry'!I65+'Defence Ministry'!I65+'Education Ministry'!I65+Crises!I65+'Breaking News'!I65+Opportunities!I65 -> 52.6 | J65: =$B65+'Economy Ministry'!J65+'Environment Ministry'!J65+'Defence Ministry'!J65+'Education Ministry'!J65+Crises!J65+'Breaking News'!J65+Opportunities!J65 -> 52.6
A66: PrivacyDataProtection | B66: 40 | C66: =$B66+'Economy Ministry'!C66+'Environment Ministry'!C66+'Defence Ministry'!C66+'Education Ministry'!C66+Crises!C66+'Breaking News'!C66+Opportunities!C66 -> 40 | D66: =$B66+'Economy Ministry'!D66+'Environment Ministry'!D66+'Defence Ministry'!D66+'Education Ministry'!D66+Crises!D66+'Breaking News'!D66+Opportunities!D66 -> 40 | E66: =$B66+'Economy Ministry'!E66+'Environment Ministry'!E66+'Defence Ministry'!E66+'Education Ministry'!E66+Crises!E66+'Breaking News'!E66+Opportunities!E66 -> 36.8 | F66: =$B66+'Economy Ministry'!F66+'Environment Ministry'!F66+'Defence Ministry'!F66+'Education Ministry'!F66+Crises!F66+'Breaking News'!F66+Opportunities!F66 -> 33.6 | G66: =$B66+'Economy Ministry'!G66+'Environment Ministry'!G66+'Defence Ministry'!G66+'Education Ministry'!G66+Crises!G66+'Breaking News'!G66+Opportunities!G66 -> 30.4 | H66: =$B66+'Economy Ministry'!H66+'Environment Ministry'!H66+'Defence Ministry'!H66+'Education Ministry'!H66+Crises!H66+'Breaking News'!H66+Opportunities!H66 -> 30.4 | I66: =$B66+'Economy Ministry'!I66+'Environment Ministry'!I66+'Defence Ministry'!I66+'Education Ministry'!I66+Crises!I66+'Breaking News'!I66+Opportunities!I66 -> 30.4 | J66: =$B66+'Economy Ministry'!J66+'Environment Ministry'!J66+'Defence Ministry'!J66+'Education Ministry'!J66+Crises!J66+'Breaking News'!J66+Opportunities!J66 -> 30.4
A67: Transparency | B67: 38 | C67: =$B67+'Economy Ministry'!C67+'Environment Ministry'!C67+'Defence Ministry'!C67+'Education Ministry'!C67+Crises!C67+'Breaking News'!C67+Opportunities!C67 -> 38 | D67: =$B67+'Economy Ministry'!D67+'Environment Ministry'!D67+'Defence Ministry'!D67+'Education Ministry'!D67+Crises!D67+'Breaking News'!D67+Opportunities!D67 -> 38 | E67: =$B67+'Economy Ministry'!E67+'Environment Ministry'!E67+'Defence Ministry'!E67+'Education Ministry'!E67+Crises!E67+'Breaking News'!E67+Opportunities!E67 -> 38 | F67: =$B67+'Economy Ministry'!F67+'Environment Ministry'!F67+'Defence Ministry'!F67+'Education Ministry'!F67+Crises!F67+'Breaking News'!F67+Opportunities!F67 -> 38 | G67: =$B67+'Economy Ministry'!G67+'Environment Ministry'!G67+'Defence Ministry'!G67+'Education Ministry'!G67+Crises!G67+'Breaking News'!G67+Opportunities!G67 -> 34.8 | H67: =$B67+'Economy Ministry'!H67+'Environment Ministry'!H67+'Defence Ministry'!H67+'Education Ministry'!H67+Crises!H67+'Breaking News'!H67+Opportunities!H67 -> 34.8 | I67: =$B67+'Economy Ministry'!I67+'Environment Ministry'!I67+'Defence Ministry'!I67+'Education Ministry'!I67+Crises!I67+'Breaking News'!I67+Opportunities!I67 -> 34.8 | J67: =$B67+'Economy Ministry'!J67+'Environment Ministry'!J67+'Defence Ministry'!J67+'Education Ministry'!J67+Crises!J67+'Breaking News'!J67+Opportunities!J67 -> 34.8
A68: SecuritySafety | B68: 45 | C68: =$B68+'Economy Ministry'!C68+'Environment Ministry'!C68+'Defence Ministry'!C68+'Education Ministry'!C68+Crises!C68+'Breaking News'!C68+Opportunities!C68 -> 45 | D68: =$B68+'Economy Ministry'!D68+'Environment Ministry'!D68+'Defence Ministry'!D68+'Education Ministry'!D68+Crises!D68+'Breaking News'!D68+Opportunities!D68 -> 43.4 | E68: =$B68+'Economy Ministry'!E68+'Environment Ministry'!E68+'Defence Ministry'!E68+'Education Ministry'!E68+Crises!E68+'Breaking News'!E68+Opportunities!E68 -> 41.8 | F68: =$B68+'Economy Ministry'!F68+'Environment Ministry'!F68+'Defence Ministry'!F68+'Education Ministry'!F68+Crises!F68+'Breaking News'!F68+Opportunities!F68 -> 38.6 | G68: =$B68+'Economy Ministry'!G68+'Environment Ministry'!G68+'Defence Ministry'!G68+'Education Ministry'!G68+Crises!G68+'Breaking News'!G68+Opportunities!G68 -> 38.6 | H68: =$B68+'Economy Ministry'!H68+'Environment Ministry'!H68+'Defence Ministry'!H68+'Education Ministry'!H68+Crises!H68+'Breaking News'!H68+Opportunities!H68 -> 38.6 | I68: =$B68+'Economy Ministry'!I68+'Environment Ministry'!I68+'Defence Ministry'!I68+'Education Ministry'!I68+Crises!I68+'Breaking News'!I68+Opportunities!I68 -> 38.6 | J68: =$B68+'Economy Ministry'!J68+'Environment Ministry'!J68+'Defence Ministry'!J68+'Education Ministry'!J68+Crises!J68+'Breaking News'!J68+Opportunities!J68 -> 38.6
A69: Accountability | B69: 38 | C69: =$B69+'Economy Ministry'!C69+'Environment Ministry'!C69+'Defence Ministry'!C69+'Education Ministry'!C69+Crises!C69+'Breaking News'!C69+Opportunities!C69 -> 38 | D69: =$B69+'Economy Ministry'!D69+'Environment Ministry'!D69+'Defence Ministry'!D69+'Education Ministry'!D69+Crises!D69+'Breaking News'!D69+Opportunities!D69 -> 38 | E69: =$B69+'Economy Ministry'!E69+'Environment Ministry'!E69+'Defence Ministry'!E69+'Education Ministry'!E69+Crises!E69+'Breaking News'!E69+Opportunities!E69 -> 38 | F69: =$B69+'Economy Ministry'!F69+'Environment Ministry'!F69+'Defence Ministry'!F69+'Education Ministry'!F69+Crises!F69+'Breaking News'!F69+Opportunities!F69 -> 38 | G69: =$B69+'Economy Ministry'!G69+'Environment Ministry'!G69+'Defence Ministry'!G69+'Education Ministry'!G69+Crises!G69+'Breaking News'!G69+Opportunities!G69 -> 34.8 | H69: =$B69+'Economy Ministry'!H69+'Environment Ministry'!H69+'Defence Ministry'!H69+'Education Ministry'!H69+Crises!H69+'Breaking News'!H69+Opportunities!H69 -> 34.8 | I69: =$B69+'Economy Ministry'!I69+'Environment Ministry'!I69+'Defence Ministry'!I69+'Education Ministry'!I69+Crises!I69+'Breaking News'!I69+Opportunities!I69 -> 34.8 | J69: =$B69+'Economy Ministry'!J69+'Environment Ministry'!J69+'Defence Ministry'!J69+'Education Ministry'!J69+Crises!J69+'Breaking News'!J69+Opportunities!J69 -> 34.8
A72: Economy
A73: AIContributionToGDP | B73: 3 | C73: =$B73+'Economy Ministry'!C73+'Environment Ministry'!C73+'Defence Ministry'!C73+'Education Ministry'!C73+Crises!C73+'Breaking News'!C73+Opportunities!C73 -> 2.68 | D73: =$B73+'Economy Ministry'!D73+'Environment Ministry'!D73+'Defence Ministry'!D73+'Education Ministry'!D73+Crises!D73+'Breaking News'!D73+Opportunities!D73 -> 2.68 | E73: =$B73+'Economy Ministry'!E73+'Environment Ministry'!E73+'Defence Ministry'!E73+'Education Ministry'!E73+Crises!E73+'Breaking News'!E73+Opportunities!E73 -> 2.68 | F73: =$B73+'Economy Ministry'!F73+'Environment Ministry'!F73+'Defence Ministry'!F73+'Education Ministry'!F73+Crises!F73+'Breaking News'!F73+Opportunities!F73 -> 2.68 | G73: =$B73+'Economy Ministry'!G73+'Environment Ministry'!G73+'Defence Ministry'!G73+'Education Ministry'!G73+Crises!G73+'Breaking News'!G73+Opportunities!G73 -> 2.68 | H73: =$B73+'Economy Ministry'!H73+'Environment Ministry'!H73+'Defence Ministry'!H73+'Education Ministry'!H73+Crises!H73+'Breaking News'!H73+Opportunities!H73 -> 2.68 | I73: =$B73+'Economy Ministry'!I73+'Environment Ministry'!I73+'Defence Ministry'!I73+'Education Ministry'!I73+Crises!I73+'Breaking News'!I73+Opportunities!I73 -> 2.68 | J73: =$B73+'Economy Ministry'!J73+'Environment Ministry'!J73+'Defence Ministry'!J73+'Education Ministry'!J73+Crises!J73+'Breaking News'!J73+Opportunities!J73 -> 2.68
A74: AIFDIStock | B74: 50000000000 | C74: =$B74+'Economy Ministry'!C74+'Environment Ministry'!C74+'Defence Ministry'!C74+'Education Ministry'!C74+Crises!C74+'Breaking News'!C74+Opportunities!C74 -> 48400000000 | D74: =$B74+'Economy Ministry'!D74+'Environment Ministry'!D74+'Defence Ministry'!D74+'Education Ministry'!D74+Crises!D74+'Breaking News'!D74+Opportunities!D74 -> 48400000000 | E74: =$B74+'Economy Ministry'!E74+'Environment Ministry'!E74+'Defence Ministry'!E74+'Education Ministry'!E74+Crises!E74+'Breaking News'!E74+Opportunities!E74 -> 48400000000 | F74: =$B74+'Economy Ministry'!F74+'Environment Ministry'!F74+'Defence Ministry'!F74+'Education Ministry'!F74+Crises!F74+'Breaking News'!F74+Opportunities!F74 -> 48400000000 | G74: =$B74+'Economy Ministry'!G74+'Environment Ministry'!G74+'Defence Ministry'!G74+'Education Ministry'!G74+Crises!G74+'Breaking News'!G74+Opportunities!G74 -> 48400000000 | H74: =$B74+'Economy Ministry'!H74+'Environment Ministry'!H74+'Defence Ministry'!H74+'Education Ministry'!H74+Crises!H74+'Breaking News'!H74+Opportunities!H74 -> 48400000000 | I74: =$B74+'Economy Ministry'!I74+'Environment Ministry'!I74+'Defence Ministry'!I74+'Education Ministry'!I74+Crises!I74+'Breaking News'!I74+Opportunities!I74 -> 48400000000 | J74: =$B74+'Economy Ministry'!J74+'Environment Ministry'!J74+'Defence Ministry'!J74+'Education Ministry'!J74+Crises!J74+'Breaking News'!J74+Opportunities!J74 -> 48400000000
A75: JobsCreated | B75: 0 | C75: =$B75+'Economy Ministry'!C75+'Environment Ministry'!C75+'Defence Ministry'!C75+'Education Ministry'!C75+Crises!C75+'Breaking News'!C75+Opportunities!C75 -> 0 | D75: =$B75+'Economy Ministry'!D75+'Environment Ministry'!D75+'Defence Ministry'!D75+'Education Ministry'!D75+Crises!D75+'Breaking News'!D75+Opportunities!D75 -> 0 | E75: =$B75+'Economy Ministry'!E75+'Environment Ministry'!E75+'Defence Ministry'!E75+'Education Ministry'!E75+Crises!E75+'Breaking News'!E75+Opportunities!E75 -> 0 | F75: =$B75+'Economy Ministry'!F75+'Environment Ministry'!F75+'Defence Ministry'!F75+'Education Ministry'!F75+Crises!F75+'Breaking News'!F75+Opportunities!F75 -> 0 | G75: =$B75+'Economy Ministry'!G75+'Environment Ministry'!G75+'Defence Ministry'!G75+'Education Ministry'!G75+Crises!G75+'Breaking News'!G75+Opportunities!G75 -> 0 | H75: =$B75+'Economy Ministry'!H75+'Environment Ministry'!H75+'Defence Ministry'!H75+'Education Ministry'!H75+Crises!H75+'Breaking News'!H75+Opportunities!H75 -> 0 | I75: =$B75+'Economy Ministry'!I75+'Environment Ministry'!I75+'Defence Ministry'!I75+'Education Ministry'!I75+Crises!I75+'Breaking News'!I75+Opportunities!I75 -> 0 | J75: =$B75+'Economy Ministry'!J75+'Environment Ministry'!J75+'Defence Ministry'!J75+'Education Ministry'!J75+Crises!J75+'Breaking News'!J75+Opportunities!J75 -> 0
A76: JobsDisplaced | B76: 0 | C76: =$B76+'Economy Ministry'!C76+'Environment Ministry'!C76+'Defence Ministry'!C76+'Education Ministry'!C76+Crises!C76+'Breaking News'!C76+Opportunities!C76 -> 0 | D76: =$B76+'Economy Ministry'!D76+'Environment Ministry'!D76+'Defence Ministry'!D76+'Education Ministry'!D76+Crises!D76+'Breaking News'!D76+Opportunities!D76 -> 0 | E76: =$B76+'Economy Ministry'!E76+'Environment Ministry'!E76+'Defence Ministry'!E76+'Education Ministry'!E76+Crises!E76+'Breaking News'!E76+Opportunities!E76 -> 0 | F76: =$B76+'Economy Ministry'!F76+'Environment Ministry'!F76+'Defence Ministry'!F76+'Education Ministry'!F76+Crises!F76+'Breaking News'!F76+Opportunities!F76 -> 0 | G76: =$B76+'Economy Ministry'!G76+'Environment Ministry'!G76+'Defence Ministry'!G76+'Education Ministry'!G76+Crises!G76+'Breaking News'!G76+Opportunities!G76 -> 0 | H76: =$B76+'Economy Ministry'!H76+'Environment Ministry'!H76+'Defence Ministry'!H76+'Education Ministry'!H76+Crises!H76+'Breaking News'!H76+Opportunities!H76 -> 0 | I76: =$B76+'Economy Ministry'!I76+'Environment Ministry'!I76+'Defence Ministry'!I76+'Education Ministry'!I76+Crises!I76+'Breaking News'!I76+Opportunities!I76 -> 0 | J76: =$B76+'Economy Ministry'!J76+'Environment Ministry'!J76+'Defence Ministry'!J76+'Education Ministry'!J76+Crises!J76+'Breaking News'!J76+Opportunities!J76 -> 0
A77: NetJobsFromAI | B77: =B75-B76 -> 0 | C77: =C75-C76 -> 0 | D77: =D75-D76 -> 0 | E77: =E75-E76 -> 0 | F77: =F75-F76 -> 0 | G77: =G75-G76 -> 0 | H77: =H75-H76 -> 0 | I77: =I75-I76 -> 0 | J77: =J75-J76 -> 0
A78: EconomyScore | B78: ='Result Targets'!B78 -> 25 | C78: ='Result Targets'!C78 -> 23.577778 | D78: ='Result Targets'!D78 -> 23.577778 | E78: ='Result Targets'!E78 -> 23.577778 | F78: ='Result Targets'!F78 -> 23.577778 | G78: ='Result Targets'!G78 -> 23.577778 | H78: ='Result Targets'!H78 -> 23.577778 | I78: ='Result Targets'!I78 -> 23.577778 | J78: ='Result Targets'!J78 -> 23.577778
A81: Environment
A82: EnergyConsumedFromDataCenters | B82: X | C82: X | D82: X | E82: X | F82: X | G82: X | H82: X | I82: X | J82: X
A83: RenewableEnergyFactor | B83: X | C83: X | D83: X | E83: X | F83: X | G83: X | H83: X | I83: X | J83: X
A84: RenewableEnergyFactor | B84: 10 | C84: =$B84+'Economy Ministry'!C84+'Environment Ministry'!C84+'Defence Ministry'!C84+'Education Ministry'!C84+Crises!C84+'Breaking News'!C84+Opportunities!C84 -> 10 | D84: =$B84+'Economy Ministry'!D84+'Environment Ministry'!D84+'Defence Ministry'!D84+'Education Ministry'!D84+Crises!D84+'Breaking News'!D84+Opportunities!D84 -> 10 | E84: =$B84+'Economy Ministry'!E84+'Environment Ministry'!E84+'Defence Ministry'!E84+'Education Ministry'!E84+Crises!E84+'Breaking News'!E84+Opportunities!E84 -> 10 | F84: =$B84+'Economy Ministry'!F84+'Environment Ministry'!F84+'Defence Ministry'!F84+'Education Ministry'!F84+Crises!F84+'Breaking News'!F84+Opportunities!F84 -> 10 | G84: =$B84+'Economy Ministry'!G84+'Environment Ministry'!G84+'Defence Ministry'!G84+'Education Ministry'!G84+Crises!G84+'Breaking News'!G84+Opportunities!G84 -> 10 | H84: =$B84+'Economy Ministry'!H84+'Environment Ministry'!H84+'Defence Ministry'!H84+'Education Ministry'!H84+Crises!H84+'Breaking News'!H84+Opportunities!H84 -> 10 | I84: =$B84+'Economy Ministry'!I84+'Environment Ministry'!I84+'Defence Ministry'!I84+'Education Ministry'!I84+Crises!I84+'Breaking News'!I84+Opportunities!I84 -> 10 | J84: =$B84+'Economy Ministry'!J84+'Environment Ministry'!J84+'Defence Ministry'!J84+'Education Ministry'!J84+Crises!J84+'Breaking News'!J84+Opportunities!J84 -> 10
A85: WaterCircularityIndex | B85: 25 | C85: =$B85+'Economy Ministry'!C85+'Environment Ministry'!C85+'Defence Ministry'!C85+'Education Ministry'!C85+Crises!C85+'Breaking News'!C85+Opportunities!C85 -> 25 | D85: =$B85+'Economy Ministry'!D85+'Environment Ministry'!D85+'Defence Ministry'!D85+'Education Ministry'!D85+Crises!D85+'Breaking News'!D85+Opportunities!D85 -> 23.4 | E85: =$B85+'Economy Ministry'!E85+'Environment Ministry'!E85+'Defence Ministry'!E85+'Education Ministry'!E85+Crises!E85+'Breaking News'!E85+Opportunities!E85 -> 23.4 | F85: =$B85+'Economy Ministry'!F85+'Environment Ministry'!F85+'Defence Ministry'!F85+'Education Ministry'!F85+Crises!F85+'Breaking News'!F85+Opportunities!F85 -> 23.4 | G85: =$B85+'Economy Ministry'!G85+'Environment Ministry'!G85+'Defence Ministry'!G85+'Education Ministry'!G85+Crises!G85+'Breaking News'!G85+Opportunities!G85 -> 23.4 | H85: =$B85+'Economy Ministry'!H85+'Environment Ministry'!H85+'Defence Ministry'!H85+'Education Ministry'!H85+Crises!H85+'Breaking News'!H85+Opportunities!H85 -> 23.4 | I85: =$B85+'Economy Ministry'!I85+'Environment Ministry'!I85+'Defence Ministry'!I85+'Education Ministry'!I85+Crises!I85+'Breaking News'!I85+Opportunities!I85 -> 23.4 | J85: =$B85+'Economy Ministry'!J85+'Environment Ministry'!J85+'Defence Ministry'!J85+'Education Ministry'!J85+Crises!J85+'Breaking News'!J85+Opportunities!J85 -> 23.4
A86: EwasteCircularityIndex | B86: 20 | C86: =$B86+'Economy Ministry'!C86+'Environment Ministry'!C86+'Defence Ministry'!C86+'Education Ministry'!C86+Crises!C86+'Breaking News'!C86+Opportunities!C86 -> 20 | D86: =$B86+'Economy Ministry'!D86+'Environment Ministry'!D86+'Defence Ministry'!D86+'Education Ministry'!D86+Crises!D86+'Breaking News'!D86+Opportunities!D86 -> 20 | E86: =$B86+'Economy Ministry'!E86+'Environment Ministry'!E86+'Defence Ministry'!E86+'Education Ministry'!E86+Crises!E86+'Breaking News'!E86+Opportunities!E86 -> 20 | F86: =$B86+'Economy Ministry'!F86+'Environment Ministry'!F86+'Defence Ministry'!F86+'Education Ministry'!F86+Crises!F86+'Breaking News'!F86+Opportunities!F86 -> 20 | G86: =$B86+'Economy Ministry'!G86+'Environment Ministry'!G86+'Defence Ministry'!G86+'Education Ministry'!G86+Crises!G86+'Breaking News'!G86+Opportunities!G86 -> 20 | H86: =$B86+'Economy Ministry'!H86+'Environment Ministry'!H86+'Defence Ministry'!H86+'Education Ministry'!H86+Crises!H86+'Breaking News'!H86+Opportunities!H86 -> 20 | I86: =$B86+'Economy Ministry'!I86+'Environment Ministry'!I86+'Defence Ministry'!I86+'Education Ministry'!I86+Crises!I86+'Breaking News'!I86+Opportunities!I86 -> 20 | J86: =$B86+'Economy Ministry'!J86+'Environment Ministry'!J86+'Defence Ministry'!J86+'Education Ministry'!J86+Crises!J86+'Breaking News'!J86+Opportunities!J86 -> 20
A87: CircularityIndex | B87: =(B85+B86)/2 -> 22.5 | C87: =(C85+C86)/2 -> 22.5 | D87: =(D85+D86)/2 -> 21.7 | E87: =(E85+E86)/2 -> 21.7 | F87: =(F85+F86)/2 -> 21.7 | G87: =(G85+G86)/2 -> 21.7 | H87: =(H85+H86)/2 -> 21.7 | I87: =(I85+I86)/2 -> 21.7 | J87: =(J85+J86)/2 -> 21.7
A88: EcosystemIntegrityIndex | B88: 25 | C88: =$B88+'Economy Ministry'!C88+'Environment Ministry'!C88+'Defence Ministry'!C88+'Education Ministry'!C88+Crises!C88+'Breaking News'!C88+Opportunities!C88 -> 25 | D88: =$B88+'Economy Ministry'!D88+'Environment Ministry'!D88+'Defence Ministry'!D88+'Education Ministry'!D88+Crises!D88+'Breaking News'!D88+Opportunities!D88 -> 25 | E88: =$B88+'Economy Ministry'!E88+'Environment Ministry'!E88+'Defence Ministry'!E88+'Education Ministry'!E88+Crises!E88+'Breaking News'!E88+Opportunities!E88 -> 25 | F88: =$B88+'Economy Ministry'!F88+'Environment Ministry'!F88+'Defence Ministry'!F88+'Education Ministry'!F88+Crises!F88+'Breaking News'!F88+Opportunities!F88 -> 25 | G88: =$B88+'Economy Ministry'!G88+'Environment Ministry'!G88+'Defence Ministry'!G88+'Education Ministry'!G88+Crises!G88+'Breaking News'!G88+Opportunities!G88 -> 25 | H88: =$B88+'Economy Ministry'!H88+'Environment Ministry'!H88+'Defence Ministry'!H88+'Education Ministry'!H88+Crises!H88+'Breaking News'!H88+Opportunities!H88 -> 25 | I88: =$B88+'Economy Ministry'!I88+'Environment Ministry'!I88+'Defence Ministry'!I88+'Education Ministry'!I88+Crises!I88+'Breaking News'!I88+Opportunities!I88 -> 25 | J88: =$B88+'Economy Ministry'!J88+'Environment Ministry'!J88+'Defence Ministry'!J88+'Education Ministry'!J88+Crises!J88+'Breaking News'!J88+Opportunities!J88 -> 25
A89: EnvironmentScore | B89: ='Result Targets'!B90 -> 34.722222 | C89: ='Result Targets'!C90 -> 34.722222 | D89: ='Result Targets'!D90 -> 34.277778 | E89: ='Result Targets'!E90 -> 34.277778 | F89: ='Result Targets'!F90 -> 34.277778 | G89: ='Result Targets'!G90 -> 34.277778 | H89: ='Result Targets'!H90 -> 34.277778 | I89: ='Result Targets'!I90 -> 34.277778 | J89: ='Result Targets'!J90 -> 34.277778
A92: Defense
A93: CybersecurityIndex | B93: 35 | C93: =$B93+'Economy Ministry'!C93+'Environment Ministry'!C93+'Defence Ministry'!C93+'Education Ministry'!C93+Crises!C93+'Breaking News'!C93+Opportunities!C93 -> 35 | D93: =$B93+'Economy Ministry'!D93+'Environment Ministry'!D93+'Defence Ministry'!D93+'Education Ministry'!D93+Crises!D93+'Breaking News'!D93+Opportunities!D93 -> 35 | E93: =$B93+'Economy Ministry'!E93+'Environment Ministry'!E93+'Defence Ministry'!E93+'Education Ministry'!E93+Crises!E93+'Breaking News'!E93+Opportunities!E93 -> 35 | F93: =$B93+'Economy Ministry'!F93+'Environment Ministry'!F93+'Defence Ministry'!F93+'Education Ministry'!F93+Crises!F93+'Breaking News'!F93+Opportunities!F93 -> 33 | G93: =$B93+'Economy Ministry'!G93+'Environment Ministry'!G93+'Defence Ministry'!G93+'Education Ministry'!G93+Crises!G93+'Breaking News'!G93+Opportunities!G93 -> 33 | H93: =$B93+'Economy Ministry'!H93+'Environment Ministry'!H93+'Defence Ministry'!H93+'Education Ministry'!H93+Crises!H93+'Breaking News'!H93+Opportunities!H93 -> 33 | I93: =$B93+'Economy Ministry'!I93+'Environment Ministry'!I93+'Defence Ministry'!I93+'Education Ministry'!I93+Crises!I93+'Breaking News'!I93+Opportunities!I93 -> 33 | J93: =$B93+'Economy Ministry'!J93+'Environment Ministry'!J93+'Defence Ministry'!J93+'Education Ministry'!J93+Crises!J93+'Breaking News'!J93+Opportunities!J93 -> 33
A94: AutonomousSystemsSafteyIndex | B94: 40 | C94: =$B94+'Economy Ministry'!C94+'Environment Ministry'!C94+'Defence Ministry'!C94+'Education Ministry'!C94+Crises!C94+'Breaking News'!C94+Opportunities!C94 -> 40 | D94: =$B94+'Economy Ministry'!D94+'Environment Ministry'!D94+'Defence Ministry'!D94+'Education Ministry'!D94+Crises!D94+'Breaking News'!D94+Opportunities!D94 -> 40 | E94: =$B94+'Economy Ministry'!E94+'Environment Ministry'!E94+'Defence Ministry'!E94+'Education Ministry'!E94+Crises!E94+'Breaking News'!E94+Opportunities!E94 -> 40 | F94: =$B94+'Economy Ministry'!F94+'Environment Ministry'!F94+'Defence Ministry'!F94+'Education Ministry'!F94+Crises!F94+'Breaking News'!F94+Opportunities!F94 -> 40 | G94: =$B94+'Economy Ministry'!G94+'Environment Ministry'!G94+'Defence Ministry'!G94+'Education Ministry'!G94+Crises!G94+'Breaking News'!G94+Opportunities!G94 -> 40 | H94: =$B94+'Economy Ministry'!H94+'Environment Ministry'!H94+'Defence Ministry'!H94+'Education Ministry'!H94+Crises!H94+'Breaking News'!H94+Opportunities!H94 -> 40 | I94: =$B94+'Economy Ministry'!I94+'Environment Ministry'!I94+'Defence Ministry'!I94+'Education Ministry'!I94+Crises!I94+'Breaking News'!I94+Opportunities!I94 -> 40 | J94: =$B94+'Economy Ministry'!J94+'Environment Ministry'!J94+'Defence Ministry'!J94+'Education Ministry'!J94+Crises!J94+'Breaking News'!J94+Opportunities!J94 -> 40
A95: DefenseExports | B95: 1000000000 | C95: =$B95+'Economy Ministry'!C95+'Environment Ministry'!C95+'Defence Ministry'!C95+'Education Ministry'!C95+Crises!C95+'Breaking News'!C95+Opportunities!C95 -> 1000000000 | D95: =$B95+'Economy Ministry'!D95+'Environment Ministry'!D95+'Defence Ministry'!D95+'Education Ministry'!D95+Crises!D95+'Breaking News'!D95+Opportunities!D95 -> 1000000000 | E95: =$B95+'Economy Ministry'!E95+'Environment Ministry'!E95+'Defence Ministry'!E95+'Education Ministry'!E95+Crises!E95+'Breaking News'!E95+Opportunities!E95 -> 1000000000 | F95: =$B95+'Economy Ministry'!F95+'Environment Ministry'!F95+'Defence Ministry'!F95+'Education Ministry'!F95+Crises!F95+'Breaking News'!F95+Opportunities!F95 -> 1000000000 | G95: =$B95+'Economy Ministry'!G95+'Environment Ministry'!G95+'Defence Ministry'!G95+'Education Ministry'!G95+Crises!G95+'Breaking News'!G95+Opportunities!G95 -> 1000000000 | H95: =$B95+'Economy Ministry'!H95+'Environment Ministry'!H95+'Defence Ministry'!H95+'Education Ministry'!H95+Crises!H95+'Breaking News'!H95+Opportunities!H95 -> 1000000000 | I95: =$B95+'Economy Ministry'!I95+'Environment Ministry'!I95+'Defence Ministry'!I95+'Education Ministry'!I95+Crises!I95+'Breaking News'!I95+Opportunities!I95 -> 1000000000 | J95: =$B95+'Economy Ministry'!J95+'Environment Ministry'!J95+'Defence Ministry'!J95+'Education Ministry'!J95+Crises!J95+'Breaking News'!J95+Opportunities!J95 -> 1000000000
A96: DefenseImports | B96: 1500000000 | C96: =$B96+'Economy Ministry'!C96+'Environment Ministry'!C96+'Defence Ministry'!C96+'Education Ministry'!C96+Crises!C96+'Breaking News'!C96+Opportunities!C96 -> 1500000000 | D96: =$B96+'Economy Ministry'!D96+'Environment Ministry'!D96+'Defence Ministry'!D96+'Education Ministry'!D96+Crises!D96+'Breaking News'!D96+Opportunities!D96 -> 1500000000 | E96: =$B96+'Economy Ministry'!E96+'Environment Ministry'!E96+'Defence Ministry'!E96+'Education Ministry'!E96+Crises!E96+'Breaking News'!E96+Opportunities!E96 -> 1500000000 | F96: =$B96+'Economy Ministry'!F96+'Environment Ministry'!F96+'Defence Ministry'!F96+'Education Ministry'!F96+Crises!F96+'Breaking News'!F96+Opportunities!F96 -> 1500000000 | G96: =$B96+'Economy Ministry'!G96+'Environment Ministry'!G96+'Defence Ministry'!G96+'Education Ministry'!G96+Crises!G96+'Breaking News'!G96+Opportunities!G96 -> 1500000000 | H96: =$B96+'Economy Ministry'!H96+'Environment Ministry'!H96+'Defence Ministry'!H96+'Education Ministry'!H96+Crises!H96+'Breaking News'!H96+Opportunities!H96 -> 1500000000 | I96: =$B96+'Economy Ministry'!I96+'Environment Ministry'!I96+'Defence Ministry'!I96+'Education Ministry'!I96+Crises!I96+'Breaking News'!I96+Opportunities!I96 -> 1500000000 | J96: =$B96+'Economy Ministry'!J96+'Environment Ministry'!J96+'Defence Ministry'!J96+'Education Ministry'!J96+Crises!J96+'Breaking News'!J96+Opportunities!J96 -> 1500000000
A97: MilitaryTechnologyTradeBalance | B97: =B95-B96 -> -500000000 | C97: =C95-C96 -> -500000000 | D97: =D95-D96 -> -500000000 | E97: =E95-E96 -> -500000000 | F97: =F95-F96 -> -500000000 | G97: =G95-G96 -> -500000000 | H97: =H95-H96 -> -500000000 | I97: =I95-I96 -> -500000000 | J97: =J95-J96 -> -500000000
A98: DefenseScore | B98: ='Result Targets'!B98 -> 35.726496 | C98: ='Result Targets'!C98 -> 35.726496 | D98: ='Result Targets'!D98 -> 35.726496 | E98: ='Result Targets'!E98 -> 35.726496 | F98: ='Result Targets'!F98 -> 34.700855 | G98: ='Result Targets'!G98 -> 34.700855 | H98: ='Result Targets'!H98 -> 34.700855 | I98: ='Result Targets'!I98 -> 34.700855 | J98: ='Result Targets'!J98 -> 34.700855
A101: Education & Innovation
A102: AILiteracy | B102: 25 | C102: =$B102+'Economy Ministry'!C102+'Environment Ministry'!C102+'Defence Ministry'!C102+'Education Ministry'!C102+Crises!C102+'Breaking News'!C102+Opportunities!C102 -> 24.2 | D102: =$B102+'Economy Ministry'!D102+'Environment Ministry'!D102+'Defence Ministry'!D102+'Education Ministry'!D102+Crises!D102+'Breaking News'!D102+Opportunities!D102 -> 24.2 | E102: =$B102+'Economy Ministry'!E102+'Environment Ministry'!E102+'Defence Ministry'!E102+'Education Ministry'!E102+Crises!E102+'Breaking News'!E102+Opportunities!E102 -> 24.2 | F102: =$B102+'Economy Ministry'!F102+'Environment Ministry'!F102+'Defence Ministry'!F102+'Education Ministry'!F102+Crises!F102+'Breaking News'!F102+Opportunities!F102 -> 24.2 | G102: =$B102+'Economy Ministry'!G102+'Environment Ministry'!G102+'Defence Ministry'!G102+'Education Ministry'!G102+Crises!G102+'Breaking News'!G102+Opportunities!G102 -> 24.2 | H102: =$B102+'Economy Ministry'!H102+'Environment Ministry'!H102+'Defence Ministry'!H102+'Education Ministry'!H102+Crises!H102+'Breaking News'!H102+Opportunities!H102 -> 24.2 | I102: =$B102+'Economy Ministry'!I102+'Environment Ministry'!I102+'Defence Ministry'!I102+'Education Ministry'!I102+Crises!I102+'Breaking News'!I102+Opportunities!I102 -> 24.2 | J102: =$B102+'Economy Ministry'!J102+'Environment Ministry'!J102+'Defence Ministry'!J102+'Education Ministry'!J102+Crises!J102+'Breaking News'!J102+Opportunities!J102 -> 24.2
A103: InnovationIndex | B103: 30 | C103: =$B103+'Economy Ministry'!C103+'Environment Ministry'!C103+'Defence Ministry'!C103+'Education Ministry'!C103+Crises!C103+'Breaking News'!C103+Opportunities!C103 -> 29.2 | D103: =$B103+'Economy Ministry'!D103+'Environment Ministry'!D103+'Defence Ministry'!D103+'Education Ministry'!D103+Crises!D103+'Breaking News'!D103+Opportunities!D103 -> 29.2 | E103: =$B103+'Economy Ministry'!E103+'Environment Ministry'!E103+'Defence Ministry'!E103+'Education Ministry'!E103+Crises!E103+'Breaking News'!E103+Opportunities!E103 -> 29.2 | F103: =$B103+'Economy Ministry'!F103+'Environment Ministry'!F103+'Defence Ministry'!F103+'Education Ministry'!F103+Crises!F103+'Breaking News'!F103+Opportunities!F103 -> 29.2 | G103: =$B103+'Economy Ministry'!G103+'Environment Ministry'!G103+'Defence Ministry'!G103+'Education Ministry'!G103+Crises!G103+'Breaking News'!G103+Opportunities!G103 -> 29.2 | H103: =$B103+'Economy Ministry'!H103+'Environment Ministry'!H103+'Defence Ministry'!H103+'Education Ministry'!H103+Crises!H103+'Breaking News'!H103+Opportunities!H103 -> 29.2 | I103: =$B103+'Economy Ministry'!I103+'Environment Ministry'!I103+'Defence Ministry'!I103+'Education Ministry'!I103+Crises!I103+'Breaking News'!I103+Opportunities!I103 -> 29.2 | J103: =$B103+'Economy Ministry'!J103+'Environment Ministry'!J103+'Defence Ministry'!J103+'Education Ministry'!J103+Crises!J103+'Breaking News'!J103+Opportunities!J103 -> 29.2
A104: InstitutionalAdoptionRate | B104: 20 | C104: =$B104+'Economy Ministry'!C104+'Environment Ministry'!C104+'Defence Ministry'!C104+'Education Ministry'!C104+Crises!C104+'Breaking News'!C104+Opportunities!C104 -> 20 | D104: =$B104+'Economy Ministry'!D104+'Environment Ministry'!D104+'Defence Ministry'!D104+'Education Ministry'!D104+Crises!D104+'Breaking News'!D104+Opportunities!D104 -> 20 | E104: =$B104+'Economy Ministry'!E104+'Environment Ministry'!E104+'Defence Ministry'!E104+'Education Ministry'!E104+Crises!E104+'Breaking News'!E104+Opportunities!E104 -> 20 | F104: =$B104+'Economy Ministry'!F104+'Environment Ministry'!F104+'Defence Ministry'!F104+'Education Ministry'!F104+Crises!F104+'Breaking News'!F104+Opportunities!F104 -> 20 | G104: =$B104+'Economy Ministry'!G104+'Environment Ministry'!G104+'Defence Ministry'!G104+'Education Ministry'!G104+Crises!G104+'Breaking News'!G104+Opportunities!G104 -> 18.4 | H104: =$B104+'Economy Ministry'!H104+'Environment Ministry'!H104+'Defence Ministry'!H104+'Education Ministry'!H104+Crises!H104+'Breaking News'!H104+Opportunities!H104 -> 18.4 | I104: =$B104+'Economy Ministry'!I104+'Environment Ministry'!I104+'Defence Ministry'!I104+'Education Ministry'!I104+Crises!I104+'Breaking News'!I104+Opportunities!I104 -> 18.4 | J104: =$B104+'Economy Ministry'!J104+'Environment Ministry'!J104+'Defence Ministry'!J104+'Education Ministry'!J104+Crises!J104+'Breaking News'!J104+Opportunities!J104 -> 18.4
A105: EducationScore | B105: ='Result Targets'!B105 -> 40.811966 | C105: ='Result Targets'!C105 -> 39.923077 | D105: ='Result Targets'!D105 -> 39.923077 | E105: ='Result Targets'!E105 -> 39.923077 | F105: ='Result Targets'!F105 -> 39.923077 | G105: ='Result Targets'!G105 -> 39.102564 | H105: ='Result Targets'!H105 -> 39.102564 | I105: ='Result Targets'!I105 -> 39.102564 | J105: ='Result Targets'!J105 -> 39.102564
A108: Weighted Governance
...

Sheet Result Targets
B1: 0 | C1: 1 | D1: 2 | E1: 3 | F1: 4 | G1: 5 | H1: 6 | I1: 7 | J1: 8
A2: Targets
A4: Economy
A5: AIContributionToGDPTarget | B5: =IF(FacilSetsTargets=1,'Target Settings'!B4,'Target Settings'!E4) -> 12 | C5: =B5 -> 12 | D5: =C5 -> 12 | E5: =D5 -> 12 | F5: =E5 -> 12 | G5: =F5 -> 12 | H5: =G5 -> 12 | I5: =H5 -> 12 | J5: =I5 -> 12
A6: AIFDIStockTarget | B6: 100000000000 | C6: =B6 -> 100000000000 | D6: =C6 -> 100000000000 | E6: =D6 -> 100000000000 | F6: =E6 -> 100000000000 | G6: =F6 -> 100000000000 | H6: =G6 -> 100000000000 | I6: =H6 -> 100000000000 | J6: =I6 -> 100000000000
A9: NetJobsFromAITarget | B9: =IF(FacilSetsTargets=1,'Target Settings'!B6,'Target Settings'!E6) -> 500000 | C9: =B9 -> 500000 | D9: =C9 -> 500000 | E9: =D9 -> 500000 | F9: =E9 -> 500000 | G9: =F9 -> 500000 | H9: =G9 -> 500000 | I9: =H9 -> 500000 | J9: =I9 -> 500000
A12: Environment
A15: RenewableEnergyFactorTarget | B15: =IF(FacilSetsTargets=1,'Target Settings'!B10,'Target Settings'!E10) -> 40 | C15: =B15 -> 40 | D15: =C15 -> 40 | E15: =D15 -> 40 | F15: =E15 -> 40 | G15: =F15 -> 40 | H15: =G15 -> 40 | I15: =H15 -> 40 | J15: =I15 -> 40
A18: CircularityIndexTarget | B18: =IF(FacilSetsTargets=1,'Target Settings'!B11,'Target Settings'!E11) -> 60 | C18: =B18 -> 60 | D18: =C18 -> 60 | E18: =D18 -> 60 | F18: =E18 -> 60 | G18: =F18 -> 60 | H18: =G18 -> 60 | I18: =H18 -> 60 | J18: =I18 -> 60
A19: EcosystemIntegrityIndexTarget | B19: =IF(FacilSetsTargets=1,'Target Settings'!B12,'Target Settings'!E12) -> 60 | C19: =B19 -> 60 | D19: =C19 -> 60 | E19: =D19 -> 60 | F19: =E19 -> 60 | G19: =F19 -> 60 | H19: =G19 -> 60 | I19: =H19 -> 60 | J19: =I19 -> 60
A22: Defense
A23: CybersecurityIndexTarget | B23: =IF(FacilSetsTargets=1,'Target Settings'!B16,'Target Settings'!E16) -> 65 | C23: =B23 -> 65 | D23: =C23 -> 65 | E23: =D23 -> 65 | F23: =E23 -> 65 | G23: =F23 -> 65 | H23: =G23 -> 65 | I23: =H23 -> 65 | J23: =I23 -> 65
A24: AutonomousSystemsSafteyIndexTarget | B24: =IF(FacilSetsTargets=1,'Target Settings'!B17,'Target Settings'!E17) -> 75 | C24: =B24 -> 75 | D24: =C24 -> 75 | E24: =D24 -> 75 | F24: =E24 -> 75 | G24: =F24 -> 75 | H24: =G24 -> 75 | I24: =H24 -> 75 | J24: =I24 -> 75
A27: MilitaryTechnologyTradeBalanceTarget | B27: =IF(FacilSetsTargets=1,'Target Settings'!B18,'Target Settings'!E18) -> 2000000000 | C27: =B27 -> 2000000000 | D27: =C27 -> 2000000000 | E27: =D27 -> 2000000000 | F27: =E27 -> 2000000000 | G27: =F27 -> 2000000000 | H27: =G27 -> 2000000000 | I27: =H27 -> 2000000000 | J27: =I27 -> 2000000000
A30: Education & Innovation
A31: AILiteracyTarget | B31: =IF(FacilSetsTargets=1,'Target Settings'!B22,'Target Settings'!E22) -> 60 | C31: =B31 -> 60 | D31: =C31 -> 60 | E31: =D31 -> 60 | F31: =E31 -> 60 | G31: =F31 -> 60 | H31: =G31 -> 60 | I31: =H31 -> 60 | J31: =I31 -> 60
A32: InnovationIndexTarget | B32: =IF(FacilSetsTargets=1,'Target Settings'!B23,'Target Settings'!E23) -> 60 | C32: =B32 -> 60 | D32: =C32 -> 60 | E32: =D32 -> 60 | F32: =E32 -> 60 | G32: =F32 -> 60 | H32: =G32 -> 60 | I32: =H32 -> 60 | J32: =I32 -> 60
A33: InstitutionalAdoptionRateTarget | B33: =IF(FacilSetsTargets=1,'Target Settings'!B24,'Target Settings'!E24) -> 65 | C33: =B33 -> 65 | D33: =C33 -> 65 | E33: =D33 -> 65 | F33: =E33 -> 65 | G33: =F33 -> 65 | H33: =G33 -> 65 | I33: =H33 -> 65 | J33: =I33 -> 65
A70: Percentage of Target Achieved %
A72: Economy
A73: AIContributionToGDPPercOfTargetAchieved | B73: =MAX((Results!B73)/('Result Targets'!B5),0) * 100 -> 25 | C73: =MAX((Results!C73)/('Result Targets'!C5),0) * 100 -> 22.333333 | D73: =MAX((Results!D73)/('Result Targets'!D5),0) * 100 -> 22.333333 | E73: =MAX((Results!E73)/('Result Targets'!E5),0) * 100 -> 22.333333 | F73: =MAX((Results!F73)/('Result Targets'!F5),0) * 100 -> 22.333333 | G73: =MAX((Results!G73)/('Result Targets'!G5),0) * 100 -> 22.333333 | H73: =MAX((Results!H73)/('Result Targets'!H5),0) * 100 -> 22.333333 | I73: =MAX((Results!I73)/('Result Targets'!I5),0) * 100 -> 22.333333 | J73: =MAX((Results!J73)/('Result Targets'!J5),0) * 100 -> 22.333333
A74: AIFDIStockPercOfTargetAchieved | B74: =MAX((Results!B74)/('Result Targets'!B6),0)*100 -> 50 | C74: =MAX((Results!C74)/('Result Targets'!C6),0)*100 -> 48.4 | D74: =MAX((Results!D74)/('Result Targets'!D6),0)*100 -> 48.4 | E74: =MAX((Results!E74)/('Result Targets'!E6),0)*100 -> 48.4 | F74: =MAX((Results!F74)/('Result Targets'!F6),0)*100 -> 48.4 | G74: =MAX((Results!G74)/('Result Targets'!G6),0)*100 -> 48.4 | H74: =MAX((Results!H74)/('Result Targets'!H6),0)*100 -> 48.4 | I74: =MAX((Results!I74)/('Result Targets'!I6),0)*100 -> 48.4 | J74: =MAX((Results!J74)/('Result Targets'!J6),0)*100 -> 48.4
A77: NetJobsFromAIPercOfTargetAchieved | B77: =MAX((Results!B77)/('Result Targets'!B9),0)*100 -> 0 | C77: =MAX((Results!C77)/('Result Targets'!C9),0)*100 -> 0 | D77: =MAX((Results!D77)/('Result Targets'!D9),0)*100 -> 0 | E77: =MAX((Results!E77)/('Result Targets'!E9),0)*100 -> 0 | F77: =MAX((Results!F77)/('Result Targets'!F9),0)*100 -> 0 | G77: =MAX((Results!G77)/('Result Targets'!G9),0)*100 -> 0 | H77: =MAX((Results!H77)/('Result Targets'!H9),0)*100 -> 0 | I77: =MAX((Results!I77)/('Result Targets'!I9),0)*100 -> 0 | J77: =MAX((Results!J77)/('Result Targets'!J9),0)*100 -> 0
A78: EconomyScore | B78: =AVERAGE(MIN(B73,100),MIN(B74,100),MIN(B77,100)) -> 25 | C78: =AVERAGE(MIN(C73,100),MIN(C74,100),MIN(C77,100)) -> 23.577778 | D78: =AVERAGE(MIN(D73,100),MIN(D74,100),MIN(D77,100)) -> 23.577778 | E78: =AVERAGE(MIN(E73,100),MIN(E74,100),MIN(E77,100)) -> 23.577778 | F78: =AVERAGE(MIN(F73,100),MIN(F74,100),MIN(F77,100)) -> 23.577778 | G78: =AVERAGE(MIN(G73,100),MIN(G74,100),MIN(G77,100)) -> 23.577778 | H78: =AVERAGE(MIN(H73,100),MIN(H74,100),MIN(H77,100)) -> 23.577778 | I78: =AVERAGE(MIN(I73,100),MIN(I74,100),MIN(I77,100)) -> 23.577778 | J78: =AVERAGE(MIN(J73,100),MIN(J74,100),MIN(J77,100)) -> 23.577778
A81: Environment
A84: RenewableEnergyFactorPercOfTargetAchieved | B84: =MAX((Results!B84)/('Result Targets'!B15),0) * 100 -> 25 | C84: =MAX((Results!C84)/('Result Targets'!C15),0) * 100 -> 25 | D84: =MAX((Results!D84)/('Result Targets'!D15),0) * 100 -> 25 | E84: =MAX((Results!E84)/('Result Targets'!E15),0) * 100 -> 25 | F84: =MAX((Results!F84)/('Result Targets'!F15),0) * 100 -> 25 | G84: =MAX((Results!G84)/('Result Targets'!G15),0) * 100 -> 25 | H84: =MAX((Results!H84)/('Result Targets'!H15),0) * 100 -> 25 | I84: =MAX((Results!I84)/('Result Targets'!I15),0) * 100 -> 25 | J84: =MAX((Results!J84)/('Result Targets'!J15),0) * 100 -> 25
A87: CircularityIndexPercOfTargetAchieved | B87: =MAX((Results!B87)/('Result Targets'!B18),0) * 100 -> 37.5 | C87: =MAX((Results!C87)/('Result Targets'!C18),0) * 100 -> 37.5 | D87: =MAX((Results!D87)/('Result Targets'!D18),0) * 100 -> 36.166667 | E87: =MAX((Results!E87)/('Result Targets'!E18),0) * 100 -> 36.166667 | F87: =MAX((Results!F87)/('Result Targets'!F18),0) * 100 -> 36.166667 | G87: =MAX((Results!G87)/('Result Targets'!G18),0) * 100 -> 36.166667 | H87: =MAX((Results!H87)/('Result Targets'!H18),0) * 100 -> 36.166667 | I87: =MAX((Results!I87)/('Result Targets'!I18),0) * 100 -> 36.166667 | J87: =MAX((Results!J87)/('Result Targets'!J18),0) * 100 -> 36.166667
A88: EcosystemIntegrityIndexPercOfTargetAchieved | B88: =MAX((Results!B88)/('Result Targets'!B19),0) * 100 -> 41.666667 | C88: =MAX((Results!C88)/('Result Targets'!C19),0) * 100 -> 41.666667 | D88: =MAX((Results!D88)/('Result Targets'!D19),0) * 100 -> 41.666667 | E88: =MAX((Results!E88)/('Result Targets'!E19),0) * 100 -> 41.666667 | F88: =MAX((Results!F88)/('Result Targets'!F19),0) * 100 -> 41.666667 | G88: =MAX((Results!G88)/('Result Targets'!G19),0) * 100 -> 41.666667 | H88: =MAX((Results!H88)/('Result Targets'!H19),0) * 100 -> 41.666667 | I88: =MAX((Results!I88)/('Result Targets'!I19),0) * 100 -> 41.666667 | J88: =MAX((Results!J88)/('Result Targets'!J19),0) * 100 -> 41.666667
A90: EnvironmentScore | B90: =AVERAGE(MIN(B84,100),MIN(B87,100),MIN(B88,100)) -> 34.722222 | C90: =AVERAGE(MIN(C84,100),MIN(C87,100),MIN(C88,100)) -> 34.722222 | D90: =AVERAGE(MIN(D84,100),MIN(D87,100),MIN(D88,100)) -> 34.277778 | E90: =AVERAGE(MIN(E84,100),MIN(E87,100),MIN(E88,100)) -> 34.277778 | F90: =AVERAGE(MIN(F84,100),MIN(F87,100),MIN(F88,100)) -> 34.277778 | G90: =AVERAGE(MIN(G84,100),MIN(G87,100),MIN(G88,100)) -> 34.277778 | H90: =AVERAGE(MIN(H84,100),MIN(H87,100),MIN(H88,100)) -> 34.277778 | I90: =AVERAGE(MIN(I84,100),MIN(I87,100),MIN(I88,100)) -> 34.277778 | J90: =AVERAGE(MIN(J84,100),MIN(J87,100),MIN(J88,100)) -> 34.277778
A92: Defense
A93: CybersecurityIndexPercOfTargetAchieved | B93: =MAX((Results!B93)/('Result Targets'!B23),0)*100 -> 53.846154 | C93: =MAX((Results!C93)/('Result Targets'!C23),0)*100 -> 53.846154 | D93: =MAX((Results!D93)/('Result Targets'!D23),0)*100 -> 53.846154 | E93: =MAX((Results!E93)/('Result Targets'!E23),0)*100 -> 53.846154 | F93: =MAX((Results!F93)/('Result Targets'!F23),0)*100 -> 50.769231 | G93: =MAX((Results!G93)/('Result Targets'!G23),0)*100 -> 50.769231 | H93: =MAX((Results!H93)/('Result Targets'!H23),0)*100 -> 50.769231 | I93: =MAX((Results!I93)/('Result Targets'!I23),0)*100 -> 50.769231 | J93: =MAX((Results!J93)/('Result Targets'!J23),0)*100 -> 50.769231
A94: AutonomousSystemsSafteyIndexPercOfTargetAchieved | B94: =MAX((Results!B94)/('Result Targets'!B24),0)*100 -> 53.333333 | C94: =MAX((Results!C94)/('Result Targets'!C24),0)*100 -> 53.333333 | D94: =MAX((Results!D94)/('Result Targets'!D24),0)*100 -> 53.333333 | E94: =MAX((Results!E94)/('Result Targets'!E24),0)*100 -> 53.333333 | F94: =MAX((Results!F94)/('Result Targets'!F24),0)*100 -> 53.333333 | G94: =MAX((Results!G94)/('Result Targets'!G24),0)*100 -> 53.333333 | H94: =MAX((Results!H94)/('Result Targets'!H24),0)*100 -> 53.333333 | I94: =MAX((Results!I94)/('Result Targets'!I24),0)*100 -> 53.333333 | J94: =MAX((Results!J94)/('Result Targets'!J24),0)*100 -> 53.333333
A97: MilitaryTechnologyTradeBalancePercOfTargetAchieved | B97: =MAX((Results!B97)/('Result Targets'!B27),0)*100 -> 0 | C97: =MAX((Results!C97)/('Result Targets'!C27),0)*100 -> 0 | D97: =MAX((Results!D97)/('Result Targets'!D27),0)*100 -> 0 | E97: =MAX((Results!E97)/('Result Targets'!E27),0)*100 -> 0 | F97: =MAX((Results!F97)/('Result Targets'!F27),0)*100 -> 0 | G97: =MAX((Results!G97)/('Result Targets'!G27),0)*100 -> 0 | H97: =MAX((Results!H97)/('Result Targets'!H27),0)*100 -> 0 | I97: =MAX((Results!I97)/('Result Targets'!I27),0)*100 -> 0 | J97: =MAX((Results!J97)/('Result Targets'!J27),0)*100 -> 0
A98: DefenseScore | B98: =AVERAGE(MIN(B93,100),MIN(B94,100),MIN(B97,100)) -> 35.726496 | C98: =AVERAGE(MIN(C93,100),MIN(C94,100),MIN(C97,100)) -> 35.726496 | D98: =AVERAGE(MIN(D93,100),MIN(D94,100),MIN(D97,100)) -> 35.726496 | E98: =AVERAGE(MIN(E93,100),MIN(E94,100),MIN(E97,100)) -> 35.726496 | F98: =AVERAGE(MIN(F93,100),MIN(F94,100),MIN(F97,100)) -> 34.700855 | G98: =AVERAGE(MIN(G93,100),MIN(G94,100),MIN(G97,100)) -> 34.700855 | H98: =AVERAGE(MIN(H93,100),MIN(H94,100),MIN(H97,100)) -> 34.700855 | I98: =AVERAGE(MIN(I93,100),MIN(I94,100),MIN(I97,100)) -> 34.700855 | J98: =AVERAGE(MIN(J93,100),MIN(J94,100),MIN(J97,100)) -> 34.700855
A101: Education & Innovation
A102: AILiteracyPercOfTargetAchieved | B102: =MAX((Results!B102)/('Result Targets'!B31),0)*100 -> 41.666667 | C102: =MAX((Results!C102)/('Result Targets'!C31),0)*100 -> 40.333333 | D102: =MAX((Results!D102)/('Result Targets'!D31),0)*100 -> 40.333333 | E102: =MAX((Results!E102)/('Result Targets'!E31),0)*100 -> 40.333333 | F102: =MAX((Results!F102)/('Result Targets'!F31),0)*100 -> 40.333333 | G102: =MAX((Results!G102)/('Result Targets'!G31),0)*100 -> 40.333333 | H102: =MAX((Results!H102)/('Result Targets'!H31),0)*100 -> 40.333333 | I102: =MAX((Results!I102)/('Result Targets'!I31),0)*100 -> 40.333333 | J102: =MAX((Results!J102)/('Result Targets'!J31),0)*100 -> 40.333333
A103: InnovationIndexPercOfTargetAchieved | B103: =MAX((Results!B103)/('Result Targets'!B32),0)*100 -> 50 | C103: =MAX((Results!C103)/('Result Targets'!C32),0)*100 -> 48.666667 | D103: =MAX((Results!D103)/('Result Targets'!D32),0)*100 -> 48.666667 | E103: =MAX((Results!E103)/('Result Targets'!E32),0)*100 -> 48.666667 | F103: =MAX((Results!F103)/('Result Targets'!F32),0)*100 -> 48.666667 | G103: =MAX((Results!G103)/('Result Targets'!G32),0)*100 -> 48.666667 | H103: =MAX((Results!H103)/('Result Targets'!H32),0)*100 -> 48.666667 | I103: =MAX((Results!I103)/('Result Targets'!I32),0)*100 -> 48.666667 | J103: =MAX((Results!J103)/('Result Targets'!J32),0)*100 -> 48.666667
A104: InstitutionalAdoptionRatePercOfTargetAchieved | B104: =MAX((Results!B104)/('Result Targets'!B33),0)*100 -> 30.769231 | C104: =MAX((Results!C104)/('Result Targets'!C33),0)*100 -> 30.769231 | D104: =MAX((Results!D104)/('Result Targets'!D33),0)*100 -> 30.769231 | E104: =MAX((Results!E104)/('Result Targets'!E33),0)*100 -> 30.769231 | F104: =MAX((Results!F104)/('Result Targets'!F33),0)*100 -> 30.769231 | G104: =MAX((Results!G104)/('Result Targets'!G33),0)*100 -> 28.307692 | H104: =MAX((Results!H104)/('Result Targets'!H33),0)*100 -> 28.307692 | I104: =MAX((Results!I104)/('Result Targets'!I33),0)*100 -> 28.307692 | J104: =MAX((Results!J104)/('Result Targets'!J33),0)*100 -> 28.307692
A105: EducationScore | B105: =AVERAGE(MIN(B102,100),MIN(B103,100),MIN(B104,100)) -> 40.811966 | C105: =AVERAGE(MIN(C102,100),MIN(C103,100),MIN(C104,100)) -> 39.923077 | D105: =AVERAGE(MIN(D102,100),MIN(D103,100),MIN(D104,100)) -> 39.923077 | E105: =AVERAGE(MIN(E102,100),MIN(E103,100),MIN(E104,100)) -> 39.923077 | F105: =AVERAGE(MIN(F102,100),MIN(F103,100),MIN(F104,100)) -> 39.923077 | G105: =AVERAGE(MIN(G102,100),MIN(G103,100),MIN(G104,100)) -> 39.102564 | H105: =AVERAGE(MIN(H102,100),MIN(H103,100),MIN(H104,100)) -> 39.102564 | I105: =AVERAGE(MIN(I102,100),MIN(I103,100),MIN(I104,100)) -> 39.102564 | J105: =AVERAGE(MIN(J102,100),MIN(J103,100),MIN(J104,100)) -> 39.102564
A108: Numbers
...

Sheet KPI Impacts
B1: Policy Impacts | K1: Slider Impacts | S1: Slider Costs
B2: HighNeg | C2: MediumNeg | D2: LowNeg | E2: None | F2: LowPos | G2: MediumPos | H2: HighPos | K2: HighNeg | L2: MediumNeg | M2: LowNeg | N2: None | O2: LowPos | P2: MediumPos | Q2: HighPos | S2: Value | T2: 0 | U2: 1 | V2: 2 | W2: 3
A63: Governance | K63: 0 | L63: 0 | M63: 0 | N63: 0 | O63: 0 | P63: 0 | Q63: 0 | S63: Cost | T63: 0 | U63: 10000000 | V63: 20000000 | W63: 40000000
A64: GrowthWellBeing | B64: =H64*-0.8 -> -2.4 | C64: =G64*-0.8 -> -1.6 | D64: =F64*-0.8 -> -0.8 | E64: 0 | F64: 1 | G64: 2 | H64: 3 | K64: =(Q64*-1)*0.6 -> -0.36 | L64: =(P64*-1)*0.6 -> -0.27 | M64: =(O64*-1)*0.6 -> -0.18 | N64: 0 | O64: 0.3 | P64: 0.45 | Q64: 0.6
A65: HumanRights | B65: =H65*-0.8 -> -2.4 | C65: =G65*-0.8 -> -1.6 | D65: =F65*-0.8 -> -0.8 | E65: 0 | F65: 1 | G65: 2 | H65: 3 | K65: =(Q65*-1)*0.6 -> -0.54 | L65: =(P65*-1)*0.6 -> -0.36 | M65: =(O65*-1)*0.6 -> -0.18 | N65: 0 | O65: 0.3 | P65: 0.6 | Q65: 0.9
A66: PrivacyDataProtection | B66: =H66*-0.8 -> -4.8 | C66: =G66*-0.8 -> -3.2 | D66: =F66*-0.8 -> -1.6 | E66: 0 | F66: 2 | G66: 4 | H66: 6 | K66: =(Q66*-1)*0.6 -> -1.08 | L66: =(P66*-1)*0.6 -> -0.72 | M66: =(O66*-1)*0.6 -> -0.36 | N66: 0 | O66: 0.6 | P66: 1.2 | Q66: 1.8
A67: Transparency | B67: =H67*-0.8 -> -4.8 | C67: =G67*-0.8 -> -3.2 | D67: =F67*-0.8 -> -1.6 | E67: 0 | F67: 2 | G67: 4 | H67: 6 | K67: =(Q67*-1)*0.6 -> -1.08 | L67: =(P67*-1)*0.6 -> -0.72 | M67: =(O67*-1)*0.6 -> -0.36 | N67: 0 | O67: 0.6 | P67: 1.2 | Q67: 1.8
A68: SecuritySafety | B68: =H68*-0.8 -> -4.8 | C68: =G68*-0.8 -> -3.2 | D68: =F68*-0.8 -> -1.6 | E68: 0 | F68: 2 | G68: 4 | H68: 6 | K68: =(Q68*-1)*0.6 -> -0.72 | L68: =(P68*-1)*0.6 -> -0.54 | M68: =(O68*-1)*0.6 -> -0.36 | N68: 0 | O68: 0.6 | P68: 0.9 | Q68: 1.2
A69: Accountability | B69: =H69*-0.8 -> -4.8 | C69: =G69*-0.8 -> -3.2 | D69: =F69*-0.8 -> -1.6 | E69: 0 | F69: 2 | G69: 4 | H69: 6 | K69: =(Q69*-1)*0.6 -> -0.72 | L69: =(P69*-1)*0.6 -> -0.54 | M69: =(O69*-1)*0.6 -> -0.36 | N69: 0 | O69: 0.6 | P69: 0.9 | Q69: 1.2
A72: Economy
A73: AIContributionToGDP | B73: =H73*-0.8 -> -0.8 | C73: =G73*-0.8 -> -0.6 | D73: =F73*-0.8 -> -0.32 | E73: 0 | F73: 0.4 | G73: 0.75 | H73: 1 | K73: =(Q73*-1)*0.6 -> -0.216 | L73: =(P73*-1)*0.6 -> -0.144 | M73: =(O73*-1)*0.6 -> -0.072 | N73: 0 | O73: 0.12 | P73: 0.24 | Q73: 0.36
A74: AIFDIStock | B74: =H74*-0.8 -> -4800000000 | C74: =G74*-0.8 -> -3200000000 | D74: =F74*-0.8 -> -1600000000 | E74: 0 | F74: 2000000000 | G74: 4000000000 | H74: 6000000000 | K74: =(Q74*-1)*0.6 -> -2160000000 | L74: =(P74*-1)*0.6 -> -1440000000 | M74: =(O74*-1)*0.6 -> -720000000 | N74: 0 | O74: 1200000000 | P74: 2400000000 | Q74: 3600000000
A75: JobsCreated | B75: =H75*-0.8 -> -60000 | C75: =G75*-0.8 -> -40000 | D75: =F75*-0.8 -> -20000 | E75: 0 | F75: 25000 | G75: 50000 | H75: 75000 | K75: =(Q75*-1)*0.6 -> -54000 | L75: =(P75*-1)*0.6 -> -54000 | M75: =(O75*-1)*0.6 -> -18000 | N75: 0 | O75: 30000 | P75: 90000 | Q75: 90000
A76: JobsDisplaced | B76: =H76*-0.8 -> -120000 | C76: =G76*-0.8 -> -80000 | D76: =F76*-0.8 -> -40000 | E76: 0 | F76: 50000 | G76: 100000 | H76: 150000 | K76: =(Q76*-1)*0.6 -> -54000 | L76: =(P76*-1)*0.6 -> -36000 | M76: =(O76*-1)*0.6 -> -18000 | N76: 0 | O76: 30000 | P76: 60000 | Q76: 90000
A77: NetJobsFromAI | B77: X | C77: X | D77: X | E77: X | F77: X | G77: X | H77: X | K77: X | L77: X | M77: X | N77: X | O77: X | P77: X | Q77: X
B78: =H78*-1 -> -5 | C78: =G78*-1 -> -3 | D78: =F78*-1 -> -1 | E78: 0 | F78: 1 | G78: 3 | H78: 5 | K78: =(Q78*-1)*0.6 -> -1.8 | L78: =(P78*-1)*0.6 -> -1.08 | M78: =(O78*-1)*0.6 -> -0.36 | N78: 0 | O78: 0.6 | P78: 1.8 | Q78: 3
A81: Environment
A82: EnergyConsumedFromDataCenters | B82: X | C82: X | D82: X | E82: X | F82: X | G82: X | H82: X | K82: X | L82: X | M82: X | N82: X | O82: X | P82: X | Q82: X
A83: CarbonIntensityFromDataCenters | B83: X | C83: X | D83: X | E83: X | F83: X | G83: X | H83: X | K83: X | L83: X | M83: X | N83: X | O83: X | P83: X | Q83: X
A84: RenewableEnergyFactor | B84: =H84*-0.8 -> -3.2 | C84: =G84*-0.8 -> -1.6 | D84: =F84*-0.8 -> -0.8 | E84: 0 | F84: 1 | G84: 2 | H84: 4 | K84: =(Q84*-1)*0.6 -> -1.44 | L84: =(P84*-1)*0.6 -> -0.72 | M84: =(O84*-1)*0.6 -> -0.36 | N84: 0 | O84: 0.6 | P84: 1.2 | Q84: 2.4
A85: WaterCircularityIndex | B85: =H85*-0.8 -> -4.8 | C85: =G85*-0.8 -> -3.2 | D85: =F85*-0.8 -> -1.6 | E85: 0 | F85: 2 | G85: 4 | H85: 6 | K85: =(Q85*-1)*0.6 -> -0.54 | L85: =(P85*-1)*0.6 -> -0.45 | M85: =(O85*-1)*0.6 -> -0.27 | N85: 0 | O85: 0.45 | P85: 0.75 | Q85: 0.9
A86: EwasteCircularityIndex | B86: =H86*-0.8 -> -4.8 | C86: =G86*-0.8 -> -3.2 | D86: =F86*-0.8 -> -1.6 | E86: 0 | F86: 2 | G86: 4 | H86: 6 | K86: =(Q86*-1)*0.6 -> -0.54 | L86: =(P86*-1)*0.6 -> -0.45 | M86: =(O86*-1)*0.6 -> -0.27 | N86: 0 | O86: 0.45 | P86: 0.75 | Q86: 0.9
A87: CircularityIndex | B87: X | C87: X | D87: X | E87: X | F87: X | G87: X | H87: X | K87: X | L87: X | M87: X | N87: X | O87: X | P87: X | Q87: X
A88: EcosystemIntegrityIndex | B88: =H88*-0.8 -> -3.2 | C88: =G88*-0.8 -> -1.6 | D88: =F88*-0.8 -> -0.8 | E88: 0 | F88: 1 | G88: 2 | H88: 4 | K88: =(Q88*-1)*0.6 -> -0.432 | L88: =(P88*-1)*0.6 -> -0.288 | M88: =(O88*-1)*0.6 -> -0.144 | N88: 0 | O88: 0.24 | P88: 0.48 | Q88: 0.72
B89: =H89*-1 -> -5 | C89: =G89*-1 -> -3 | D89: =F89*-1 -> -1 | E89: 0 | F89: 1 | G89: 3 | H89: 5 | K89: =(Q89*-1)*0.6 -> -1.8 | L89: =(P89*-1)*0.6 -> -1.08 | M89: =(O89*-1)*0.6 -> -0.36 | N89: 0 | O89: 0.6 | P89: 1.8 | Q89: 3
A92: Defense
A93: CybersecurityIndex | B93: =H93*-0.8 -> -2 | C93: =G93*-0.8 -> -1.2 | D93: =F93*-0.8 -> -0.8 | E93: 0 | F93: 1 | G93: 1.5 | H93: 2.5 | K93: =(Q93*-1)*0.6 -> -0.54 | L93: =(P93*-1)*0.6 -> -0.36 | M93: =(O93*-1)*0.6 -> -0.18 | N93: 0 | O93: 0.3 | P93: 0.6 | Q93: 0.9
A94: AutonomousSystemsSafteyIndex | B94: =H94*-0.8 -> -2 | C94: =G94*-0.8 -> -1.2 | D94: =F94*-0.8 -> -0.8 | E94: 0 | F94: 1 | G94: 1.5 | H94: 2.5 | K94: =(Q94*-1)*0.6 -> -0.54 | L94: =(P94*-1)*0.6 -> -0.36 | M94: =(O94*-1)*0.6 -> -0.18 | N94: 0 | O94: 0.3 | P94: 0.6 | Q94: 0.9
A95: DefenseExports | B95: =H95*-0.8 -> -1200000000 | C95: =G95*-0.8 -> -800000000 | D95: =F95*-0.8 -> -320000000 | E95: 0 | F95: 400000000 | G95: 1000000000 | H95: 1500000000 | K95: =(Q95*-1)*0.6 -> -270000000 | L95: =(P95*-1)*0.6 -> -144000000 | M95: =(O95*-1)*0.6 -> -54000000 | N95: 0 | O95: 90000000 | P95: 240000000 | Q95: 450000000
A96: DefenseImports | B96: =H96*-0.8 -> -600000000 | C96: =G96*-0.8 -> -320000000 | D96: =F96*-0.8 -> -120000000 | E96: 0 | F96: 150000000 | G96: 400000000 | H96: 750000000 | K96: =(Q96*-1)*0.6 -> -270000000 | L96: =(P96*-1)*0.6 -> -144000000 | M96: =(O96*-1)*0.6 -> -54000000 | N96: 0 | O96: 90000000 | P96: 240000000 | Q96: 450000000
A97: MilitaryTechnologyTradeBalance | B97: X | C97: X | D97: X | E97: X | F97: X | G97: X | H97: X | K97: X | L97: X | M97: X | N97: X | O97: X | P97: X | Q97: X
B98: =H98*-1 -> -5 | C98: =G98*-1 -> -3 | D98: =F98*-1 -> -1 | E98: 0 | F98: 1 | G98: 3 | H98: 5 | K98: =(Q98*-1)*0.6 -> -1.8 | L98: =(P98*-1)*0.6 -> -1.08 | M98: =(O98*-1)*0.6 -> -0.36 | N98: 0 | O98: 0.6 | P98: 1.8 | Q98: 3
A101: Education & Innovation
A102: AILiteracy | B102: =H102*-0.8 -> -3.2 | C102: =G102*-0.8 -> -1.6 | D102: =F102*-0.8 -> -0.8 | E102: 0 | F102: 1 | G102: 2 | H102: 4 | K102: =(Q102*-1)*0.6 -> -1.08 | L102: =(P102*-1)*0.6 -> -0.72 | M102: =(O102*-1)*0.6 -> -0.36 | N102: 0 | O102: 0.6 | P102: 1.2 | Q102: 1.8
A103: InnovationIndex | B103: =H103*-0.8 -> -1.2 | C103: =G103*-0.8 -> -0.8 | D103: =F103*-0.8 -> -0.4 | E103: 0 | F103: 0.5 | G103: 1 | H103: 1.5 | K103: =(Q103*-1)*0.6 -> -0.54 | L103: =(P103*-1)*0.6 -> -0.36 | M103: =(O103*-1)*0.6 -> -0.18 | N103: 0 | O103: 0.3 | P103: 0.6 | Q103: 0.9
A104: InstitutionalAdoptionRate | B104: =H104*-0.8 -> -4.8 | C104: =G104*-0.8 -> -3.2 | D104: =F104*-0.8 -> -1.6 | E104: 0 | F104: 2 | G104: 4 | H104: 6 | K104: =(Q104*-1)*0.6 -> -1.44 | L104: =(P104*-1)*0.6 -> -0.72 | M104: =(O104*-1)*0.6 -> -0.36 | N104: 0 | O104: 0.6 | P104: 1.2 | Q104: 2.4

Sheet Economy Ministry
