Workbook
Name _C1: Crises!$P$5:$X$5
Name _C1Enabled: Crises!$P$7:$X$7
Name _C1Prepared: Crises!$P$8:$X$8
Name _C1Show: Crises!$P$6:$X$6
Name _C1ShowCrisisCard: Crises!$P$9:$X$9
Name _C1Year: Crises!$P$4:$X$4
Name _C2: Crises!$AD$5:$AL$5
Name _C2Enabled: Crises!$AD$7:$AL$7
Name _C2Prepared: Crises!$AD$8:$AL$8
Name _C2Show: Crises!$AD$6:$AL$6
Name _C2ShowCrisisCard: Crises!$AD$9:$AL$9
Name _C2Year: Crises!$AD$4:$AL$4
Name _C3: Crises!$AR$5:$AZ$5
Name _C3Enabled: Crises!$AR$7:$AZ$7
Name _C3Prepared: Crises!$AR$8:$AZ$8
Name _C3Show: Crises!$AR$6:$AZ$6
Name _C3ShowCrisisCard: Crises!$AR$9:$AZ$9
Name _C3Year: Crises!$AR$4:$AZ$4
Name _C4: Crises!$BF$5:$BN$5
Name _C4Enabled: Crises!$BF$7:$BN$7
Name _C4Prepared: Crises!$BF$8:$BN$8
Name _C4Show: Crises!$BF$6:$BN$6
Name _C4ShowCrisisCard: Crises!$BF$9:$BN$9
Name _C4Year: Crises!$BF$4:$BN$4
Name _C5: Crises!$BT$5:$CB$5
Name _C5Enabled: Crises!$BT$7:$CB$7
Name _C5Prepared: Crises!$BT$8:$CB$8
Name _C5Show: Crises!$BT$6:$CB$6
Name _C5ShowCrisisCard: Crises!$BT$9:$CB$9
Name _C5Year: Crises!$BT$4:$CB$4
Name _C6: Crises!$CH$5:$CP$5
Name _C6Enabled: Crises!$CH$7:$CP$7
Name _C6Prepared: Crises!$CH$8:$CP$8
Name _C6Show: Crises!$CH$6:$CP$6
Name _C6ShowCrisisCard: Crises!$CH$9:$CP$9
Name _C6Year: Crises!$CH$4:$CP$4
Name Accountability: Results!$B$69:$J$69
Name AIContributionToGDP: Results!$B$73:$J$73
Name AIContributionToGDPPercOfTargetAchieved: 'Result Targets'!$B$73:$J$73
Name AIContributionToGDPTarget: 'Result Targets'!$B$5:$J$5
Name AIFDIStock: Results!$B$74:$J$74
Name AIFDIStockPercOfTargetAchieved: 'Result Targets'!$B$74:$J$74
Name AIFDIStockTarget: 'Result Targets'!$B$6:$J$6
Name AIFeedbackEnabled: 'Project Variables'!$B$8
Name AILiteracy: Results!$B$102:$J$102
Name AILiteracyPercOfTargetAchieved: 'Result Targets'!$B$102:$J$102
Name AILiteracyTarget: 'Result Targets'!$B$31:$J$31
Name AutonomousSystemsSafteyIndex: Results!$B$94:$J$94
Name AutonomousSystemsSafteyIndexPercOfTargetAchieved: 'Result Targets'!$B$94:$J$94
Name AutonomousSystemsSafteyIndexTarget: 'Result Targets'!$B$24:$J$24
Name AverageMinistryScore: Results!$B$118:$J$118
Name CarbonIntensityFromDataCenters: Results!$B$83:$J$83
Name CircularityIndex: Results!$B$87:$J$87
Name CircularityIndexPercOfTargetAchieved: 'Result Targets'!$B$87:$J$87
Name CircularityIndexTarget: 'Result Targets'!$B$18:$J$18
Name CumulativeStartupImpactYear: Startups!$B$6:$H$6
Name CybersecurityIndex: Results!$B$93:$J$93
Name CybersecurityIndexPercOfTargetAchieved: 'Result Targets'!$B$93:$J$93
Name CybersecurityIndexTarget: 'Result Targets'!$B$23:$J$23
Name DefAvaialbleToAllocate: 'Defence Ministry'!$B$111:$J$111

Sheet Project Variables
A1: ModelKitID | B1: aigov
A2: settingsID | B2: 0
A3: ReadVault | B3: 0
A4: NumYears | B4: 5
A5: GameOver | B5: =IF(Step=NumYears,1,0) -> 0
A7: Misc
A8: AIFeedbackEnabled | B8: 0
A9: IsMultiplayer | B9: 0
A10: SliderReasoningEnabled | B10: 0
A11: TeamName
A13: Confirmed / Ready
A14: EcConfirmed | B14: 0
A15: EnvConfirmed | B15: 0
A16: DefConfirmed | B16: 0
A17: EduConfirmed | B17: 0
A19: Enabled Ministries
A20: EcEnabled | B20: 1
A21: EnvEnabled | B21: 1
A22: DefEnabled | B22: 1
A23: EduEnabled | B23: 1
A24: FacEcEnabled | B24: 1
A25: FacEnvEnabled | B25: 1
A26: FacDefEnabled | B26: 1
A27: FacEduEnabled | B27: 1
A28: FacAllowMinistryChoice | B28: 1
A29: MinistriesConfirmed | B29: 0
A31: Role Selection
A32: RoleUser0 | B32: 0
A33: RoleUser1 | B33: 0
A34: RoleUser2 | B34: 0
A35: RoleUser3 | B35: 0
A36: RoleUser4 | B36: 0
A37: RolesConfirmed | B37: 0
D38: Position | E38: 1 | F38: 2 | G38: 3 | H38: 4 | I38: 5 | J38: 6
A39: Values | D39: Weight | E39: 0.25 | F39: 0.25 | G39: 0.15 | H39: 0.15 | I39: 0.1 | J39: 0.1
A40: Value1Position | B40: 1 | D40: Growth & Welbeing | E40: =_xlfn.XLOOKUP(Value1Position,$E$38:$J$38,$E$39:$J$39) -> 0.25
A41: Value2Position | B41: 2 | D41: Human Rights | E41: =_xlfn.XLOOKUP(Value2Position,$E$38:$J$38,$E$39:$J$39) -> 0.25
A42: Value3Position | B42: 3 | D42: Privacy & Data Protection | E42: =_xlfn.XLOOKUP(Value3Position,$E$38:$J$38,$E$39:$J$39) -> 0.15
A43: Value4Position | B43: 4 | D43: Transparency | E43: =_xlfn.XLOOKUP(Value4Position,$E$38:$J$38,$E$39:$J$39) -> 0.15
A44: Value5Position | B44: 5 | D44: Security & Safety | E44: =_xlfn.XLOOKUP(Value5Position,$E$38:$J$38,$E$39:$J$39) -> 0.1
...

Sheet Target Settings
A1: FacilSetsTargets | B1: 0
A3: Economy | E3: Defaults
A4: F_AIContributionToGDPTarget | B4: =E4 -> 12 | E4: 12
A5: F_AIFDIStockTarget | B5: =E5 -> 2.5 | E5: 2.5
A6: F_NetJobsFromAITarget | B6: =E6 -> 500000 | E6: 500000
A9: Environment
A10: F_RenewableEnergyFactorTarget | B10: =E10 -> 40 | E10: 40
A11: F_CircularityIndexTarget | B11: =E11 -> 60 | E11: 60
A12: F_EcosystemIntegrityIndexTarget | B12: =E12 -> 60 | E12: 60
A15: Defense
A16: F_CybersecurityIndexTarget | B16: =E16 -> 65 | E16: 65
A17: F_AutonomousSystemsSafteyIndexTarget | B17: =E17 -> 75 | E17: 75
A18: F_MilitaryTechnologyTradeBalanceTarget | B18: =E18 -> 2000000000 | E18: 2000000000
A21: Education & Innovation
A22: F_AILiteracyTarget | B22: =E22 -> 60 | E22: 60
A23: F_InnovationIndexTarget | B23: =E23 -> 60 | E23: 60
A24: F_InstitutionalAdoptionRateTarget | B24: =E24 -> 65 | E24: 65

Sheet Results
A1: Public Policy Simulation: AI Governance
A3: Step | B3: 0
A5: Time | B5: 0 | C5: 1 | D5: 2 | E5: 3 | F5: 4 | G5: 5 | H5: 6 | I5: 7 | J5: 8
A6: Year | B6: 1 | C6: 2 | D6: 3 | E6: 4 | F6: 5 | G6: 6 | H6: 7 | I6: 8 | J6: 9
A63: Governance
A64: GrowthWellBeing | B64: 50 | C64: =$B64+'Economy Ministry'!C64*EcEnabled+'Environment Ministry'!C64*EnvEnabled+'Defence Ministry'!C64*DefEnabled+'Education Ministry'!C64*EduEnabled+Crises!C64+'Breaking News'!C64+Dilemmas!C64+Startups!C64 -> 50 | D64: =$B64+'Economy Ministry'!D64*EcEnabled+'Environment Ministry'!D64*EnvEnabled+'Defence Ministry'!D64*DefEnabled+'Education Ministry'!D64*EduEnabled+Crises!D64+'Breaking News'!D64+Dilemmas!D64+Startups!D64 -> 50 | E64: =$B64+'Economy Ministry'!E64*EcEnabled+'Environment Ministry'!E64*EnvEnabled+'Defence Ministry'!E64*DefEnabled+'Education Ministry'!E64*EduEnabled+Crises!E64+'Breaking News'!E64+Dilemmas!E64+Startups!E64 -> 50 | F64: =$B64+'Economy Ministry'!F64*EcEnabled+'Environment Ministry'!F64*EnvEnabled+'Defence Ministry'!F64*DefEnabled+'Education Ministry'!F64*EduEnabled+Crises!F64+'Breaking News'!F64+Dilemmas!F64+Startups!F64 -> 50 | G64: =$B64+'Economy Ministry'!G64*EcEnabled+'Environment Ministry'!G64*EnvEnabled+'Defence Ministry'!G64*DefEnabled+'Education Ministry'!G64*EduEnabled+Crises!G64+'Breaking News'!G64+Dilemmas!G64+Startups!G64 -> 50 | H64: =$B64+'Economy Ministry'!H64*EcEnabled+'Environment Ministry'!H64*EnvEnabled+'Defence Ministry'!H64*DefEnabled+'Education Ministry'!H64*EduEnabled+Crises!H64+'Breaking News'!H64+Dilemmas!H64+Startups!H64 -> 50 | I64: =$B64+'Economy Ministry'!I64*EcEnabled+'Environment Ministry'!I64*EnvEnabled+'Defence Ministry'!I64*DefEnabled+'Education Ministry'!I64*EduEnabled+Crises!I64+'Breaking News'!I64+Dilemmas!I64 -> 50 | J64: =$B64+'Economy Ministry'!J64*EcEnabled+'Environment Ministry'!J64*EnvEnabled+'Defence Ministry'!J64*DefEnabled+'Education Ministry'!J64*EduEnabled+Crises!J64+'Breaking News'!J64+Dilemmas!J64 -> 50
A65: HumanRights | B65: 55 | C65: =$B65+'Economy Ministry'!C65*EcEnabled+'Environment Ministry'!C65*EnvEnabled+'Defence Ministry'!C65*DefEnabled+'Education Ministry'!C65*EduEnabled+Crises!C65+'Breaking News'!C65+Dilemmas!C65+Startups!C65 -> 55 | D65: =$B65+'Economy Ministry'!D65*EcEnabled+'Environment Ministry'!D65*EnvEnabled+'Defence Ministry'!D65*DefEnabled+'Education Ministry'!D65*EduEnabled+Crises!D65+'Breaking News'!D65+Dilemmas!D65+Startups!D65 -> 53.4 | E65: =$B65+'Economy Ministry'!E65*EcEnabled+'Environment Ministry'!E65*EnvEnabled+'Defence Ministry'!E65*DefEnabled+'Education Ministry'!E65*EduEnabled+Crises!E65+'Breaking News'!E65+Dilemmas!E65+Startups!E65 -> 53.4 | F65: =$B65+'Economy Ministry'!F65*EcEnabled+'Environment Ministry'!F65*EnvEnabled+'Defence Ministry'!F65*DefEnabled+'Education Ministry'!F65*EduEnabled+Crises!F65+'Breaking News'!F65+Dilemmas!F65+Startups!F65 -> 53.4 | G65: =$B65+'Economy Ministry'!G65*EcEnabled+'Environment Ministry'!G65*EnvEnabled+'Defence Ministry'!G65*DefEnabled+'Education Ministry'!G65*EduEnabled+Crises!G65+'Breaking News'!G65+Dilemmas!G65+Startups!G65 -> 53.4 | H65: =$B65+'Economy Ministry'!H65*EcEnabled+'Environment Ministry'!H65*EnvEnabled+'Defence Ministry'!H65*DefEnabled+'Education Ministry'!H65*EduEnabled+Crises!H65+'Breaking News'!H65+Dilemmas!H65+Startups!H65 -> 53.4 | I65: =$B65+'Economy Ministry'!I65*EcEnabled+'Environment Ministry'!I65*EnvEnabled+'Defence Ministry'!I65*DefEnabled+'Education Ministry'!I65*EduEnabled+Crises!I65+'Breaking News'!I65+Dilemmas!I65 -> 53.4 | J65: =$B65+'Economy Ministry'!J65*EcEnabled+'Environment Ministry'!J65*EnvEnabled+'Defence Ministry'!J65*DefEnabled+'Education Ministry'!J65*EduEnabled+Crises!J65+'Breaking News'!J65+Dilemmas!J65 -> 53.4
A66: PrivacyDataProtection | B66: 40 | C66: =$B66+'Economy Ministry'!C66*EcEnabled+'Environment Ministry'!C66*EnvEnabled+'Defence Ministry'!C66*DefEnabled+'Education Ministry'!C66*EduEnabled+Crises!C66+'Breaking News'!C66+Dilemmas!C66+Startups!C66 -> 40 | D66: =$B66+'Economy Ministry'!D66*EcEnabled+'Environment Ministry'!D66*EnvEnabled+'Defence Ministry'!D66*DefEnabled+'Education Ministry'!D66*EduEnabled+Crises!D66+'Breaking News'!D66+Dilemmas!D66+Startups!D66 -> 40 | E66: =$B66+'Economy Ministry'!E66*EcEnabled+'Environment Ministry'!E66*EnvEnabled+'Defence Ministry'!E66*DefEnabled+'Education Ministry'!E66*EduEnabled+Crises!E66+'Breaking News'!E66+Dilemmas!E66+Startups!E66 -> 40 | F66: =$B66+'Economy Ministry'!F66*EcEnabled+'Environment Ministry'!F66*EnvEnabled+'Defence Ministry'!F66*DefEnabled+'Education Ministry'!F66*EduEnabled+Crises!F66+'Breaking News'!F66+Dilemmas!F66+Startups!F66 -> 40 | G66: =$B66+'Economy Ministry'!G66*EcEnabled+'Environment Ministry'!G66*EnvEnabled+'Defence Ministry'!G66*DefEnabled+'Education Ministry'!G66*EduEnabled+Crises!G66+'Breaking News'!G66+Dilemmas!G66+Startups!G66 -> 40 | H66: =$B66+'Economy Ministry'!H66*EcEnabled+'Environment Ministry'!H66*EnvEnabled+'Defence Ministry'!H66*DefEnabled+'Education Ministry'!H66*EduEnabled+Crises!H66+'Breaking News'!H66+Dilemmas!H66+Startups!H66 -> 40 | I66: =$B66+'Economy Ministry'!I66*EcEnabled+'Environment Ministry'!I66*EnvEnabled+'Defence Ministry'!I66*DefEnabled+'Education Ministry'!I66*EduEnabled+Crises!I66+'Breaking News'!I66+Dilemmas!I66 -> 40 | J66: =$B66+'Economy Ministry'!J66*EcEnabled+'Environment Ministry'!J66*EnvEnabled+'Defence Ministry'!J66*DefEnabled+'Education Ministry'!J66*EduEnabled+Crises!J66+'Breaking News'!J66+Dilemmas!J66 -> 40
A67: Transparency | B67: 38 | C67: =$B67+'Economy Ministry'!C67*EcEnabled+'Environment Ministry'!C67*EnvEnabled+'Defence Ministry'!C67*DefEnabled+'Education Ministry'!C67*EduEnabled+Crises!C67+'Breaking News'!C67+Dilemmas!C67+Startups!C67 -> 38 | D67: =$B67+'Economy Ministry'!D67*EcEnabled+'Environment Ministry'!D67*EnvEnabled+'Defence Ministry'!D67*DefEnabled+'Education Ministry'!D67*EduEnabled+Crises!D67+'Breaking News'!D67+Dilemmas!D67+Startups!D67 -> 36.4 | E67: =$B67+'Economy Ministry'!E67*EcEnabled+'Environment Ministry'!E67*EnvEnabled+'Defence Ministry'!E67*DefEnabled+'Education Ministry'!E67*EduEnabled+Crises!E67+'Breaking News'!E67+Dilemmas!E67+Startups!E67 -> 36.4 | F67: =$B67+'Economy Ministry'!F67*EcEnabled+'Environment Ministry'!F67*EnvEnabled+'Defence Ministry'!F67*DefEnabled+'Education Ministry'!F67*EduEnabled+Crises!F67+'Breaking News'!F67+Dilemmas!F67+Startups!F67 -> 36.4 | G67: =$B67+'Economy Ministry'!G67*EcEnabled+'Environment Ministry'!G67*EnvEnabled+'Defence Ministry'!G67*DefEnabled+'Education Ministry'!G67*EduEnabled+Crises!G67+'Breaking News'!G67+Dilemmas!G67+Startups!G67 -> 36.4 | H67: =$B67+'Economy Ministry'!H67*EcEnabled+'Environment Ministry'!H67*EnvEnabled+'Defence Ministry'!H67*DefEnabled+'Education Ministry'!H67*EduEnabled+Crises!H67+'Breaking News'!H67+Dilemmas!H67+Startups!H67 -> 34.8 | I67: =$B67+'Economy Ministry'!I67*EcEnabled+'Environment Ministry'!I67*EnvEnabled+'Defence Ministry'!I67*DefEnabled+'Education Ministry'!I67*EduEnabled+Crises!I67+'Breaking News'!I67+Dilemmas!I67 -> 34.8 | J67: =$B67+'Economy Ministry'!J67*EcEnabled+'Environment Ministry'!J67*EnvEnabled+'Defence Ministry'!J67*DefEnabled+'Education Ministry'!J67*EduEnabled+Crises!J67+'Breaking News'!J67+Dilemmas!J67 -> 34.8
A68: SecuritySafety | B68: 45 | C68: =$B68+'Economy Ministry'!C68*EcEnabled+'Environment Ministry'!C68*EnvEnabled+'Defence Ministry'!C68*DefEnabled+'Education Ministry'!C68*EduEnabled+Crises!C68+'Breaking News'!C68+Dilemmas!C68+Startups!C68 -> 45 | D68: =$B68+'Economy Ministry'!D68*EcEnabled+'Environment Ministry'!D68*EnvEnabled+'Defence Ministry'!D68*DefEnabled+'Education Ministry'!D68*EduEnabled+Crises!D68+'Breaking News'!D68+Dilemmas!D68+Startups!D68 -> 45 | E68: =$B68+'Economy Ministry'!E68*EcEnabled+'Environment Ministry'!E68*EnvEnabled+'Defence Ministry'!E68*DefEnabled+'Education Ministry'!E68*EduEnabled+Crises!E68+'Breaking News'!E68+Dilemmas!E68+Startups!E68 -> 45 | F68: =$B68+'Economy Ministry'!F68*EcEnabled+'Environment Ministry'!F68*EnvEnabled+'Defence Ministry'!F68*DefEnabled+'Education Ministry'!F68*EduEnabled+Crises!F68+'Breaking News'!F68+Dilemmas!F68+Startups!F68 -> 45 | G68: =$B68+'Economy Ministry'!G68*EcEnabled+'Environment Ministry'!G68*EnvEnabled+'Defence Ministry'!G68*DefEnabled+'Education Ministry'!G68*EduEnabled+Crises!G68+'Breaking News'!G68+Dilemmas!G68+Startups!G68 -> 45 | H68: =$B68+'Economy Ministry'!H68*EcEnabled+'Environment Ministry'!H68*EnvEnabled+'Defence Ministry'!H68*DefEnabled+'Education Ministry'!H68*EduEnabled+Crises!H68+'Breaking News'!H68+Dilemmas!H68+Startups!H68 -> 45 | I68: =$B68+'Economy Ministry'!I68*EcEnabled+'Environment Ministry'!I68*EnvEnabled+'Defence Ministry'!I68*DefEnabled+'Education Ministry'!I68*EduEnabled+Crises!I68+'Breaking News'!I68+Dilemmas!I68 -> 45 | J68: =$B68+'Economy Ministry'!J68*EcEnabled+'Environment Ministry'!J68*EnvEnabled+'Defence Ministry'!J68*DefEnabled+'Education Ministry'!J68*EduEnabled+Crises!J68+'Breaking News'!J68+Dilemmas!J68 -> 45
A69: Accountability | B69: 38 | C69: =$B69+'Economy Ministry'!C69*EcEnabled+'Environment Ministry'!C69*EnvEnabled+'Defence Ministry'!C69*DefEnabled+'Education Ministry'!C69*EduEnabled+Crises!C69+'Breaking News'!C69+Dilemmas!C69+Startups!C69 -> 38 | D69: =$B69+'Economy Ministry'!D69*EcEnabled+'Environment Ministry'!D69*EnvEnabled+'Defence Ministry'!D69*DefEnabled+'Education Ministry'!D69*EduEnabled+Crises!D69+'Breaking News'!D69+Dilemmas!D69+Startups!D69 -> 34.8 | E69: =$B69+'Economy Ministry'!E69*EcEnabled+'Environment Ministry'!E69*EnvEnabled+'Defence Ministry'!E69*DefEnabled+'Education Ministry'!E69*EduEnabled+Crises!E69+'Breaking News'!E69+Dilemmas!E69+Startups!E69 -> 34.8 | F69: =$B69+'Economy Ministry'!F69*EcEnabled+'Environment Ministry'!F69*EnvEnabled+'Defence Ministry'!F69*DefEnabled+'Education Ministry'!F69*EduEnabled+Crises!F69+'Breaking News'!F69+Dilemmas!F69+Startups!F69 -> 34.8 | G69: =$B69+'Economy Ministry'!G69*EcEnabled+'Environment Ministry'!G69*EnvEnabled+'Defence Ministry'!G69*DefEnabled+'Education Ministry'!G69*EduEnabled+Crises!G69+'Breaking News'!G69+Dilemmas!G69+Startups!G69 -> 34.8 | H69: =$B69+'Economy Ministry'!H69*EcEnabled+'Environment Ministry'!H69*EnvEnabled+'Defence Ministry'!H69*DefEnabled+'Education Ministry'!H69*EduEnabled+Crises!H69+'Breaking News'!H69+Dilemmas!H69+Startups!H69 -> 31.6 | I69: =$B69+'Economy Ministry'!I69*EcEnabled+'Environment Ministry'!I69*EnvEnabled+'Defence Ministry'!I69*DefEnabled+'Education Ministry'!I69*EduEnabled+Crises!I69+'Breaking News'!I69+Dilemmas!I69 -> 31.6 | J69: =$B69+'Economy Ministry'!J69*EcEnabled+'Environment Ministry'!J69*EnvEnabled+'Defence Ministry'!J69*DefEnabled+'Education Ministry'!J69*EduEnabled+Crises!J69+'Breaking News'!J69+Dilemmas!J69 -> 31.6
A72: Economy
A73: AIContributionToGDP | B73: 3 | C73: =$B73+'Economy Ministry'!C73*EcEnabled+'Environment Ministry'!C73*EnvEnabled+'Defence Ministry'!C73*DefEnabled+'Education Ministry'!C73*EduEnabled+Crises!C73+'Breaking News'!C73+Dilemmas!C73+Startups!C73 -> 2.68 | D73: =$B73+'Economy Ministry'!D73*EcEnabled+'Environment Ministry'!D73*EnvEnabled+'Defence Ministry'!D73*DefEnabled+'Education Ministry'!D73*EduEnabled+Crises!D73+'Breaking News'!D73+Dilemmas!D73+Startups!D73 -> 2.68 | E73: =$B73+'Economy Ministry'!E73*EcEnabled+'Environment Ministry'!E73*EnvEnabled+'Defence Ministry'!E73*DefEnabled+'Education Ministry'!E73*EduEnabled+Crises!E73+'Breaking News'!E73+Dilemmas!E73+Startups!E73 -> 2.68 | F73: =$B73+'Economy Ministry'!F73*EcEnabled+'Environment Ministry'!F73*EnvEnabled+'Defence Ministry'!F73*DefEnabled+'Education Ministry'!F73*EduEnabled+Crises!F73+'Breaking News'!F73+Dilemmas!F73+Startups!F73 -> 2.68 | G73: =$B73+'Economy Ministry'!G73*EcEnabled+'Environment Ministry'!G73*EnvEnabled+'Defence Ministry'!G73*DefEnabled+'Education Ministry'!G73*EduEnabled+Crises!G73+'Breaking News'!G73+Dilemmas!G73+Startups!G73 -> 2.68 | H73: =$B73+'Economy Ministry'!H73*EcEnabled+'Environment Ministry'!H73*EnvEnabled+'Defence Ministry'!H73*DefEnabled+'Education Ministry'!H73*EduEnabled+Crises!H73+'Breaking News'!H73+Dilemmas!H73+Startups!H73 -> 3.08 | I73: =$B73+'Economy Ministry'!I73*EcEnabled+'Environment Ministry'!I73*EnvEnabled+'Defence Ministry'!I73*DefEnabled+'Education Ministry'!I73*EduEnabled+Crises!I73+'Breaking News'!I73+Dilemmas!I73 -> 3.08 | J73: =$B73+'Economy Ministry'!J73*EcEnabled+'Environment Ministry'!J73*EnvEnabled+'Defence Ministry'!J73*DefEnabled+'Education Ministry'!J73*EduEnabled+Crises!J73+'Breaking News'!J73+Dilemmas!J73 -> 3.08
A74: AIFDIStock | B74: 50000000000 | C74: =$B74+'Economy Ministry'!C74*EcEnabled+'Environment Ministry'!C74*EnvEnabled+'Defence Ministry'!C74*DefEnabled+'Education Ministry'!C74*EduEnabled+Crises!C74+'Breaking News'!C74+Dilemmas!C74+Startups!C74 -> 46800000000 | D74: =$B74+'Economy Ministry'!D74*EcEnabled+'Environment Ministry'!D74*EnvEnabled+'Defence Ministry'!D74*DefEnabled+'Education Ministry'!D74*EduEnabled+Crises!D74+'Breaking News'!D74+Dilemmas!D74+Startups!D74 -> 46800000000 | E74: =$B74+'Economy Ministry'!E74*EcEnabled+'Environment Ministry'!E74*EnvEnabled+'Defence Ministry'!E74*DefEnabled+'Education Ministry'!E74*EduEnabled+Crises!E74+'Breaking News'!E74+Dilemmas!E74+Startups!E74 -> 45200000000 | F74: =$B74+'Economy Ministry'!F74*EcEnabled+'Environment Ministry'!F74*EnvEnabled+'Defence Ministry'!F74*DefEnabled+'Education Ministry'!F74*EduEnabled+Crises!F74+'Breaking News'!F74+Dilemmas!F74+Startups!F74 -> 45200000000 | G74: =$B74+'Economy Ministry'!G74*EcEnabled+'Environment Ministry'!G74*EnvEnabled+'Defence Ministry'!G74*DefEnabled+'Education Ministry'!G74*EduEnabled+Crises!G74+'Breaking News'!G74+Dilemmas!G74+Startups!G74 -> 42000000000 | H74: =$B74+'Economy Ministry'!H74*EcEnabled+'Environment Ministry'!H74*EnvEnabled+'Defence Ministry'!H74*DefEnabled+'Education Ministry'!H74*EduEnabled+Crises!H74+'Breaking News'!H74+Dilemmas!H74+Startups!H74 -> 42000000000 | I74: =$B74+'Economy Ministry'!I74*EcEnabled+'Environment Ministry'!I74*EnvEnabled+'Defence Ministry'!I74*DefEnabled+'Education Ministry'!I74*EduEnabled+Crises!I74+'Breaking News'!I74+Dilemmas!I74 -> 42000000000 | J74: =$B74+'Economy Ministry'!J74*EcEnabled+'Environment Ministry'!J74*EnvEnabled+'Defence Ministry'!J74*DefEnabled+'Education Ministry'!J74*EduEnabled+Crises!J74+'Breaking News'!J74+Dilemmas!J74 -> 42000000000
A75: JobsCreated | B75: 0 | C75: =$B75+'Economy Ministry'!C75*EcEnabled+'Environment Ministry'!C75*EnvEnabled+'Defence Ministry'!C75*DefEnabled+'Education Ministry'!C75*EduEnabled+Crises!C75+'Breaking News'!C75+Dilemmas!C75+Startups!C75 -> 0 | D75: =$B75+'Economy Ministry'!D75*EcEnabled+'Environment Ministry'!D75*EnvEnabled+'Defence Ministry'!D75*DefEnabled+'Education Ministry'!D75*EduEnabled+Crises!D75+'Breaking News'!D75+Dilemmas!D75+Startups!D75 -> 0 | E75: =$B75+'Economy Ministry'!E75*EcEnabled+'Environment Ministry'!E75*EnvEnabled+'Defence Ministry'!E75*DefEnabled+'Education Ministry'!E75*EduEnabled+Crises!E75+'Breaking News'!E75+Dilemmas!E75+Startups!E75 -> 0 | F75: =$B75+'Economy Ministry'!F75*EcEnabled+'Environment Ministry'!F75*EnvEnabled+'Defence Ministry'!F75*DefEnabled+'Education Ministry'!F75*EduEnabled+Crises!F75+'Breaking News'!F75+Dilemmas!F75+Startups!F75 -> 0 | G75: =$B75+'Economy Ministry'!G75*EcEnabled+'Environment Ministry'!G75*EnvEnabled+'Defence Ministry'!G75*DefEnabled+'Education Ministry'!G75*EduEnabled+Crises!G75+'Breaking News'!G75+Dilemmas!G75+Startups!G75 -> 0 | H75: =$B75+'Economy Ministry'!H75*EcEnabled+'Environment Ministry'!H75*EnvEnabled+'Defence Ministry'!H75*DefEnabled+'Education Ministry'!H75*EduEnabled+Crises!H75+'Breaking News'!H75+Dilemmas!H75+Startups!H75 -> 0 | I75: =$B75+'Economy Ministry'!I75*EcEnabled+'Environment Ministry'!I75*EnvEnabled+'Defence Ministry'!I75*DefEnabled+'Education Ministry'!I75*EduEnabled+Crises!I75+'Breaking News'!I75+Dilemmas!I75 -> 0 | J75: =$B75+'Economy Ministry'!J75*EcEnabled+'Environment Ministry'!J75*EnvEnabled+'Defence Ministry'!J75*DefEnabled+'Education Ministry'!J75*EduEnabled+Crises!J75+'Breaking News'!J75+Dilemmas!J75 -> 0
A76: JobsDisplaced | B76: 0 | C76: =$B76+'Economy Ministry'!C76*EcEnabled+'Environment Ministry'!C76*EnvEnabled+'Defence Ministry'!C76*DefEnabled+'Education Ministry'!C76*EduEnabled+Crises!C76+'Breaking News'!C76+Dilemmas!C76+Startups!C76 -> 0 | D76: =$B76+'Economy Ministry'!D76*EcEnabled+'Environment Ministry'!D76*EnvEnabled+'Defence Ministry'!D76*DefEnabled+'Education Ministry'!D76*EduEnabled+Crises!D76+'Breaking News'!D76+Dilemmas!D76+Startups!D76 -> 0 | E76: =$B76+'Economy Ministry'!E76*EcEnabled+'Environment Ministry'!E76*EnvEnabled+'Defence Ministry'!E76*DefEnabled+'Education Ministry'!E76*EduEnabled+Crises!E76+'Breaking News'!E76+Dilemmas!E76+Startups!E76 -> 0 | F76: =$B76+'Economy Ministry'!F76*EcEnabled+'Environment Ministry'!F76*EnvEnabled+'Defence Ministry'!F76*DefEnabled+'Education Ministry'!F76*EduEnabled+Crises!F76+'Breaking News'!F76+Dilemmas!F76+Startups!F76 -> 0 | G76: =$B76+'Economy Ministry'!G76*EcEnabled+'Environment Ministry'!G76*EnvEnabled+'Defence Ministry'!G76*DefEnabled+'Education Ministry'!G76*EduEnabled+Crises!G76+'Breaking News'!G76+Dilemmas!G76+Startups!G76 -> 0 | H76: =$B76+'Economy Ministry'!H76*EcEnabled+'Environment Ministry'!H76*EnvEnabled+'Defence Ministry'!H76*DefEnabled+'Education Ministry'!H76*EduEnabled+Crises!H76+'Breaking News'!H76+Dilemmas!H76+Startups!H76 -> 0 | I76: =$B76+'Economy Ministry'!I76*EcEnabled+'Environment Ministry'!I76*EnvEnabled+'Defence Ministry'!I76*DefEnabled+'Education Ministry'!I76*EduEnabled+Crises!I76+'Breaking News'!I76+Dilemmas!I76 -> 0 | J76: =$B76+'Economy Ministry'!J76*EcEnabled+'Environment Ministry'!J76*EnvEnabled+'Defence Ministry'!J76*DefEnabled+'Education Ministry'!J76*EduEnabled+Crises!J76+'Breaking News'!J76+Dilemmas!J76 -> 0
A77: NetJobsFromAI | B77: =B75-B76 -> 0 | C77: =C75-C76 -> 0 | D77: =D75-D76 -> 0 | E77: =E75-E76 -> 0 | F77: =F75-F76 -> 0 | G77: =G75-G76 -> 0 | H77: =H75-H76 -> 0 | I77: =I75-I76 -> 0 | J77: =J75-J76 -> 0
A78: EconomyScore | B78: ='Result Targets'!B78 -> 25 | C78: ='Result Targets'!C78 -> 23.044444 | D78: ='Result Targets'!D78 -> 23.044444 | E78: ='Result Targets'!E78 -> 22.511111 | F78: ='Result Targets'!F78 -> 22.511111 | G78: ='Result Targets'!G78 -> 21.444444 | H78: ='Result Targets'!H78 -> 22.555556 | I78: ='Result Targets'!I78 -> 22.555556 | J78: ='Result Targets'!J78 -> 22.555556
A81: Environment
A82: EnergyConsumedFromDataCenters | B82: X | C82: X | D82: X | E82: X | F82: X | G82: X | H82: X | I82: X | J82: X
A83: RenewableEnergyFactor | B83: X | C83: X | D83: X | E83: X | F83: X | G83: X | H83: X | I83: X | J83: X
A84: RenewableEnergyFactor | B84: 10 | C84: =$B84+'Economy Ministry'!C84*EcEnabled+'Environment Ministry'!C84*EnvEnabled+'Defence Ministry'!C84*DefEnabled+'Education Ministry'!C84*EduEnabled+Crises!C84+'Breaking News'!C84+Dilemmas!C84+Startups!C84 -> 10 | D84: =$B84+'Economy Ministry'!D84*EcEnabled+'Environment Ministry'!D84*EnvEnabled+'Defence Ministry'!D84*DefEnabled+'Education Ministry'!D84*EduEnabled+Crises!D84+'Breaking News'!D84+Dilemmas!D84+Startups!D84 -> 10 | E84: =$B84+'Economy Ministry'!E84*EcEnabled+'Environment Ministry'!E84*EnvEnabled+'Defence Ministry'!E84*DefEnabled+'Education Ministry'!E84*EduEnabled+Crises!E84+'Breaking News'!E84+Dilemmas!E84+Startups!E84 -> 10 | F84: =$B84+'Economy Ministry'!F84*EcEnabled+'Environment Ministry'!F84*EnvEnabled+'Defence Ministry'!F84*DefEnabled+'Education Ministry'!F84*EduEnabled+Crises!F84+'Breaking News'!F84+Dilemmas!F84+Startups!F84 -> 10 | G84: =$B84+'Economy Ministry'!G84*EcEnabled+'Environment Ministry'!G84*EnvEnabled+'Defence Ministry'!G84*DefEnabled+'Education Ministry'!G84*EduEnabled+Crises!G84+'Breaking News'!G84+Dilemmas!G84+Startups!G84 -> 10 | H84: =$B84+'Economy Ministry'!H84*EcEnabled+'Environment Ministry'!H84*EnvEnabled+'Defence Ministry'!H84*DefEnabled+'Education Ministry'!H84*EduEnabled+Crises!H84+'Breaking News'!H84+Dilemmas!H84+Startups!H84 -> 10 | I84: =$B84+'Economy Ministry'!I84*EcEnabled+'Environment Ministry'!I84*EnvEnabled+'Defence Ministry'!I84*DefEnabled+'Education Ministry'!I84*EduEnabled+Crises!I84+'Breaking News'!I84+Dilemmas!I84 -> 10 | J84: =$B84+'Economy Ministry'!J84*EcEnabled+'Environment Ministry'!J84*EnvEnabled+'Defence Ministry'!J84*DefEnabled+'Education Ministry'!J84*EduEnabled+Crises!J84+'Breaking News'!J84+Dilemmas!J84 -> 10
A85: WaterCircularityIndex | B85: 25 | C85: =$B85+'Economy Ministry'!C85*EcEnabled+'Environment Ministry'!C85*EnvEnabled+'Defence Ministry'!C85*DefEnabled+'Education Ministry'!C85*EduEnabled+Crises!C85+'Breaking News'!C85+Dilemmas!C85+Startups!C85 -> 25 | D85: =$B85+'Economy Ministry'!D85*EcEnabled+'Environment Ministry'!D85*EnvEnabled+'Defence Ministry'!D85*DefEnabled+'Education Ministry'!D85*EduEnabled+Crises!D85+'Breaking News'!D85+Dilemmas!D85+Startups!D85 -> 25 | E85: =$B85+'Economy Ministry'!E85*EcEnabled+'Environment Ministry'!E85*EnvEnabled+'Defence Ministry'!E85*DefEnabled+'Education Ministry'!E85*EduEnabled+Crises!E85+'Breaking News'!E85+Dilemmas!E85+Startups!E85 -> 25 | F85: =$B85+'Economy Ministry'!F85*EcEnabled+'Environment Ministry'!F85*EnvEnabled+'Defence Ministry'!F85*DefEnabled+'Education Ministry'!F85*EduEnabled+Crises!F85+'Breaking News'!F85+Dilemmas!F85+Startups!F85 -> 25 | G85: =$B85+'Economy Ministry'!G85*EcEnabled+'Environment Ministry'!G85*EnvEnabled+'Defence Ministry'!G85*DefEnabled+'Education Ministry'!G85*EduEnabled+Crises!G85+'Breaking News'!G85+Dilemmas!G85+Startups!G85 -> 25 | H85: =$B85+'Economy Ministry'!H85*EcEnabled+'Environment Ministry'!H85*EnvEnabled+'Defence Ministry'!H85*DefEnabled+'Education Ministry'!H85*EduEnabled+Crises!H85+'Breaking News'!H85+Dilemmas!H85+Startups!H85 -> 25 | I85: =$B85+'Economy Ministry'!I85*EcEnabled+'Environment Ministry'!I85*EnvEnabled+'Defence Ministry'!I85*DefEnabled+'Education Ministry'!I85*EduEnabled+Crises!I85+'Breaking News'!I85+Dilemmas!I85 -> 25 | J85: =$B85+'Economy Ministry'!J85*EcEnabled+'Environment Ministry'!J85*EnvEnabled+'Defence Ministry'!J85*DefEnabled+'Education Ministry'!J85*EduEnabled+Crises!J85+'Breaking News'!J85+Dilemmas!J85 -> 25
A86: EwasteCircularityIndex | B86: 20 | C86: =$B86+'Economy Ministry'!C86*EcEnabled+'Environment Ministry'!C86*EnvEnabled+'Defence Ministry'!C86*DefEnabled+'Education Ministry'!C86*EduEnabled+Crises!C86+'Breaking News'!C86+Dilemmas!C86+Startups!C86 -> 20 | D86: =$B86+'Economy Ministry'!D86*EcEnabled+'Environment Ministry'!D86*EnvEnabled+'Defence Ministry'!D86*DefEnabled+'Education Ministry'!D86*EduEnabled+Crises!D86+'Breaking News'!D86+Dilemmas!D86+Startups!D86 -> 20 | E86: =$B86+'Economy Ministry'!E86*EcEnabled+'Environment Ministry'!E86*EnvEnabled+'Defence Ministry'!E86*DefEnabled+'Education Ministry'!E86*EduEnabled+Crises!E86+'Breaking News'!E86+Dilemmas!E86+Startups!E86 -> 20 | F86: =$B86+'Economy Ministry'!F86*EcEnabled+'Environment Ministry'!F86*EnvEnabled+'Defence Ministry'!F86*DefEnabled+'Education Ministry'!F86*EduEnabled+Crises!F86+'Breaking News'!F86+Dilemmas!F86+Startups!F86 -> 20 | G86: =$B86+'Economy Ministry'!G86*EcEnabled+'Environment Ministry'!G86*EnvEnabled+'Defence Ministry'!G86*DefEnabled+'Education Ministry'!G86*EduEnabled+Crises!G86+'Breaking News'!G86+Dilemmas!G86+Startups!G86 -> 20 | H86: =$B86+'Economy Ministry'!H86*EcEnabled+'Environment Ministry'!H86*EnvEnabled+'Defence Ministry'!H86*DefEnabled+'Education Ministry'!H86*EduEnabled+Crises!H86+'Breaking News'!H86+Dilemmas!H86+Startups!H86 -> 20 | I86: =$B86+'Economy Ministry'!I86*EcEnabled+'Environment Ministry'!I86*EnvEnabled+'Defence Ministry'!I86*DefEnabled+'Education Ministry'!I86*EduEnabled+Crises!I86+'Breaking News'!I86+Dilemmas!I86 -> 20 | J86: =$B86+'Economy Ministry'!J86*EcEnabled+'Environment Ministry'!J86*EnvEnabled+'Defence Ministry'!J86*DefEnabled+'Education Ministry'!J86*EduEnabled+Crises!J86+'Breaking News'!J86+Dilemmas!J86 -> 20
A87: CircularityIndex | B87: =(B85+B86)/2 -> 22.5 | C87: =(C85+C86)/2 -> 22.5 | D87: =(D85+D86)/2 -> 22.5 | E87: =(E85+E86)/2 -> 22.5 | F87: =(F85+F86)/2 -> 22.5 | G87: =(G85+G86)/2 -> 22.5 | H87: =(H85+H86)/2 -> 22.5 | I87: =(I85+I86)/2 -> 22.5 | J87: =(J85+J86)/2 -> 22.5
A88: EcosystemIntegrityIndex | B88: 25 | C88: =$B88+'Economy Ministry'!C88*EcEnabled+'Environment Ministry'!C88*EnvEnabled+'Defence Ministry'!C88*DefEnabled+'Education Ministry'!C88*EduEnabled+Crises!C88+'Breaking News'!C88+Dilemmas!C88+Startups!C88 -> 25 | D88: =$B88+'Economy Ministry'!D88*EcEnabled+'Environment Ministry'!D88*EnvEnabled+'Defence Ministry'!D88*DefEnabled+'Education Ministry'!D88*EduEnabled+Crises!D88+'Breaking News'!D88+Dilemmas!D88+Startups!D88 -> 25 | E88: =$B88+'Economy Ministry'!E88*EcEnabled+'Environment Ministry'!E88*EnvEnabled+'Defence Ministry'!E88*DefEnabled+'Education Ministry'!E88*EduEnabled+Crises!E88+'Breaking News'!E88+Dilemmas!E88+Startups!E88 -> 25 | F88: =$B88+'Economy Ministry'!F88*EcEnabled+'Environment Ministry'!F88*EnvEnabled+'Defence Ministry'!F88*DefEnabled+'Education Ministry'!F88*EduEnabled+Crises!F88+'Breaking News'!F88+Dilemmas!F88+Startups!F88 -> 25 | G88: =$B88+'Economy Ministry'!G88*EcEnabled+'Environment Ministry'!G88*EnvEnabled+'Defence Ministry'!G88*DefEnabled+'Education Ministry'!G88*EduEnabled+Crises!G88+'Breaking News'!G88+Dilemmas!G88+Startups!G88 -> 25 | H88: =$B88+'Economy Ministry'!H88*EcEnabled+'Environment Ministry'!H88*EnvEnabled+'Defence Ministry'!H88*DefEnabled+'Education Ministry'!H88*EduEnabled+Crises!H88+'Breaking News'!H88+Dilemmas!H88+Startups!H88 -> 25 | I88: =$B88+'Economy Ministry'!I88*EcEnabled+'Environment Ministry'!I88*EnvEnabled+'Defence Ministry'!I88*DefEnabled+'Education Ministry'!I88*EduEnabled+Crises!I88+'Breaking News'!I88+Dilemmas!I88 -> 25 | J88: =$B88+'Economy Ministry'!J88*EcEnabled+'Environment Ministry'!J88*EnvEnabled+'Defence Ministry'!J88*DefEnabled+'Education Ministry'!J88*EduEnabled+Crises!J88+'Breaking News'!J88+Dilemmas!J88 -> 25
A89: EnvironmentScore | B89: ='Result Targets'!B90 -> 34.722222 | C89: ='Result Targets'!C90 -> 34.722222 | D89: ='Result Targets'!D90 -> 34.722222 | E89: ='Result Targets'!E90 -> 34.722222 | F89: ='Result Targets'!F90 -> 34.722222 | G89: ='Result Targets'!G90 -> 34.722222 | H89: ='Result Targets'!H90 -> 34.722222 | I89: ='Result Targets'!I90 -> 34.722222 | J89: ='Result Targets'!J90 -> 34.722222
A92: Defense
A93: CybersecurityIndex | B93: 35 | C93: =$B93+'Economy Ministry'!C93*EcEnabled+'Environment Ministry'!C93*EnvEnabled+'Defence Ministry'!C93*DefEnabled+'Education Ministry'!C93*EduEnabled+Crises!C93+'Breaking News'!C93+Dilemmas!C93+Startups!C93 -> 35 | D93: =$B93+'Economy Ministry'!D93*EcEnabled+'Environment Ministry'!D93*EnvEnabled+'Defence Ministry'!D93*DefEnabled+'Education Ministry'!D93*EduEnabled+Crises!D93+'Breaking News'!D93+Dilemmas!D93+Startups!D93 -> 35 | E93: =$B93+'Economy Ministry'!E93*EcEnabled+'Environment Ministry'!E93*EnvEnabled+'Defence Ministry'!E93*DefEnabled+'Education Ministry'!E93*EduEnabled+Crises!E93+'Breaking News'!E93+Dilemmas!E93+Startups!E93 -> 35 | F93: =$B93+'Economy Ministry'!F93*EcEnabled+'Environment Ministry'!F93*EnvEnabled+'Defence Ministry'!F93*DefEnabled+'Education Ministry'!F93*EduEnabled+Crises!F93+'Breaking News'!F93+Dilemmas!F93+Startups!F93 -> 35 | G93: =$B93+'Economy Ministry'!G93*EcEnabled+'Environment Ministry'!G93*EnvEnabled+'Defence Ministry'!G93*DefEnabled+'Education Ministry'!G93*EduEnabled+Crises!G93+'Breaking News'!G93+Dilemmas!G93+Startups!G93 -> 35 | H93: =$B93+'Economy Ministry'!H93*EcEnabled+'Environment Ministry'!H93*EnvEnabled+'Defence Ministry'!H93*DefEnabled+'Education Ministry'!H93*EduEnabled+Crises!H93+'Breaking News'!H93+Dilemmas!H93+Startups!H93 -> 35 | I93: =$B93+'Economy Ministry'!I93*EcEnabled+'Environment Ministry'!I93*EnvEnabled+'Defence Ministry'!I93*DefEnabled+'Education Ministry'!I93*EduEnabled+Crises!I93+'Breaking News'!I93+Dilemmas!I93 -> 35 | J93: =$B93+'Economy Ministry'!J93*EcEnabled+'Environment Ministry'!J93*EnvEnabled+'Defence Ministry'!J93*DefEnabled+'Education Ministry'!J93*EduEnabled+Crises!J93+'Breaking News'!J93+Dilemmas!J93 -> 35
A94: AutonomousSystemsSafteyIndex | B94: 40 | C94: =$B94+'Economy Ministry'!C94*EcEnabled+'Environment Ministry'!C94*EnvEnabled+'Defence Ministry'!C94*DefEnabled+'Education Ministry'!C94*EduEnabled+Crises!C94+'Breaking News'!C94+Dilemmas!C94+Startups!C94 -> 40 | D94: =$B94+'Economy Ministry'!D94*EcEnabled+'Environment Ministry'!D94*EnvEnabled+'Defence Ministry'!D94*DefEnabled+'Education Ministry'!D94*EduEnabled+Crises!D94+'Breaking News'!D94+Dilemmas!D94+Startups!D94 -> 39.2 | E94: =$B94+'Economy Ministry'!E94*EcEnabled+'Environment Ministry'!E94*EnvEnabled+'Defence Ministry'!E94*DefEnabled+'Education Ministry'!E94*EduEnabled+Crises!E94+'Breaking News'!E94+Dilemmas!E94+Startups!E94 -> 39.2 | F94: =$B94+'Economy Ministry'!F94*EcEnabled+'Environment Ministry'!F94*EnvEnabled+'Defence Ministry'!F94*DefEnabled+'Education Ministry'!F94*EduEnabled+Crises!F94+'Breaking News'!F94+Dilemmas!F94+Startups!F94 -> 39.2 | G94: =$B94+'Economy Ministry'!G94*EcEnabled+'Environment Ministry'!G94*EnvEnabled+'Defence Ministry'!G94*DefEnabled+'Education Ministry'!G94*EduEnabled+Crises!G94+'Breaking News'!G94+Dilemmas!G94+Startups!G94 -> 39.2 | H94: =$B94+'Economy Ministry'!H94*EcEnabled+'Environment Ministry'!H94*EnvEnabled+'Defence Ministry'!H94*DefEnabled+'Education Ministry'!H94*EduEnabled+Crises!H94+'Breaking News'!H94+Dilemmas!H94+Startups!H94 -> 39.2 | I94: =$B94+'Economy Ministry'!I94*EcEnabled+'Environment Ministry'!I94*EnvEnabled+'Defence Ministry'!I94*DefEnabled+'Education Ministry'!I94*EduEnabled+Crises!I94+'Breaking News'!I94+Dilemmas!I94 -> 39.2 | J94: =$B94+'Economy Ministry'!J94*EcEnabled+'Environment Ministry'!J94*EnvEnabled+'Defence Ministry'!J94*DefEnabled+'Education Ministry'!J94*EduEnabled+Crises!J94+'Breaking News'!J94+Dilemmas!J94 -> 39.2
A95: DefenseExports | B95: 1000000000 | C95: =$B95+'Economy Ministry'!C95*EcEnabled+'Environment Ministry'!C95*EnvEnabled+'Defence Ministry'!C95*DefEnabled+'Education Ministry'!C95*EduEnabled+Crises!C95+'Breaking News'!C95+Dilemmas!C95+Startups!C95 -> 1000000000 | D95: =$B95+'Economy Ministry'!D95*EcEnabled+'Environment Ministry'!D95*EnvEnabled+'Defence Ministry'!D95*DefEnabled+'Education Ministry'!D95*EduEnabled+Crises!D95+'Breaking News'!D95+Dilemmas!D95+Startups!D95 -> 1000000000 | E95: =$B95+'Economy Ministry'!E95*EcEnabled+'Environment Ministry'!E95*EnvEnabled+'Defence Ministry'!E95*DefEnabled+'Education Ministry'!E95*EduEnabled+Crises!E95+'Breaking News'!E95+Dilemmas!E95+Startups!E95 -> 1000000000 | F95: =$B95+'Economy Ministry'!F95*EcEnabled+'Environment Ministry'!F95*EnvEnabled+'Defence Ministry'!F95*DefEnabled+'Education Ministry'!F95*EduEnabled+Crises!F95+'Breaking News'!F95+Dilemmas!F95+Startups!F95 -> 1000000000 | G95: =$B95+'Economy Ministry'!G95*EcEnabled+'Environment Ministry'!G95*EnvEnabled+'Defence Ministry'!G95*DefEnabled+'Education Ministry'!G95*EduEnabled+Crises!G95+'Breaking News'!G95+Dilemmas!G95+Startups!G95 -> 1000000000 | H95: =$B95+'Economy Ministry'!H95*EcEnabled+'Environment Ministry'!H95*EnvEnabled+'Defence Ministry'!H95*DefEnabled+'Education Ministry'!H95*EduEnabled+Crises!H95+'Breaking News'!H95+Dilemmas!H95+Startups!H95 -> 1000000000 | I95: =$B95+'Economy Ministry'!I95*EcEnabled+'Environment Ministry'!I95*EnvEnabled+'Defence Ministry'!I95*DefEnabled+'Education Ministry'!I95*EduEnabled+Crises!I95+'Breaking News'!I95+Dilemmas!I95 -> 1000000000 | J95: =$B95+'Economy Ministry'!J95*EcEnabled+'Environment Ministry'!J95*EnvEnabled+'Defence Ministry'!J95*DefEnabled+'Education Ministry'!J95*EduEnabled+Crises!J95+'Breaking News'!J95+Dilemmas!J95 -> 1000000000
A96: DefenseImports | B96: 1500000000 | C96: =$B96+'Economy Ministry'!C96*EcEnabled+'Environment Ministry'!C96*EnvEnabled+'Defence Ministry'!C96*DefEnabled+'Education Ministry'!C96*EduEnabled+Crises!C96+'Breaking News'!C96+Dilemmas!C96+Startups!C96 -> 1500000000 | D96: =$B96+'Economy Ministry'!D96*EcEnabled+'Environment Ministry'!D96*EnvEnabled+'Defence Ministry'!D96*DefEnabled+'Education Ministry'!D96*EduEnabled+Crises!D96+'Breaking News'!D96+Dilemmas!D96+Startups!D96 -> 1380000000 | E96: =$B96+'Economy Ministry'!E96*EcEnabled+'Environment Ministry'!E96*EnvEnabled+'Defence Ministry'!E96*DefEnabled+'Education Ministry'!E96*EduEnabled+Crises!E96+'Breaking News'!E96+Dilemmas!E96+Startups!E96 -> 1380000000 | F96: =$B96+'Economy Ministry'!F96*EcEnabled+'Environment Ministry'!F96*EnvEnabled+'Defence Ministry'!F96*DefEnabled+'Education Ministry'!F96*EduEnabled+Crises!F96+'Breaking News'!F96+Dilemmas!F96+Startups!F96 -> 1380000000 | G96: =$B96+'Economy Ministry'!G96*EcEnabled+'Environment Ministry'!G96*EnvEnabled+'Defence Ministry'!G96*DefEnabled+'Education Ministry'!G96*EduEnabled+Crises!G96+'Breaking News'!G96+Dilemmas!G96+Startups!G96 -> 1380000000 | H96: =$B96+'Economy Ministry'!H96*EcEnabled+'Environment Ministry'!H96*EnvEnabled+'Defence Ministry'!H96*DefEnabled+'Education Ministry'!H96*EduEnabled+Crises!H96+'Breaking News'!H96+Dilemmas!H96+Startups!H96 -> 1380000000 | I96: =$B96+'Economy Ministry'!I96*EcEnabled+'Environment Ministry'!I96*EnvEnabled+'Defence Ministry'!I96*DefEnabled+'Education Ministry'!I96*EduEnabled+Crises!I96+'Breaking News'!I96+Dilemmas!I96 -> 1380000000 | J96: =$B96+'Economy Ministry'!J96*EcEnabled+'Environment Ministry'!J96*EnvEnabled+'Defence Ministry'!J96*DefEnabled+'Education Ministry'!J96*EduEnabled+Crises!J96+'Breaking News'!J96+Dilemmas!J96 -> 1380000000
A97: MilitaryTechnologyTradeBalance | B97: =B95-B96 -> -500000000 | C97: =C95-C96 -> -500000000 | D97: =D95-D96 -> -380000000 | E97: =E95-E96 -> -380000000 | F97: =F95-F96 -> -380000000 | G97: =G95-G96 -> -380000000 | H97: =H95-H96 -> -380000000 | I97: =I95-I96 -> -380000000 | J97: =J95-J96 -> -380000000
A98: DefenseScore | B98: ='Result Targets'!B98 -> 35.726496 | C98: ='Result Targets'!C98 -> 35.726496 | D98: ='Result Targets'!D98 -> 35.37094 | E98: ='Result Targets'!E98 -> 35.37094 | F98: ='Result Targets'!F98 -> 35.37094 | G98: ='Result Targets'!G98 -> 35.37094 | H98: ='Result Targets'!H98 -> 35.37094 | I98: ='Result Targets'!I98 -> 35.37094 | J98: ='Result Targets'!J98 -> 35.37094
A101: Education & Innovation
A102: AILiteracy | B102: 25 | C102: =$B102+'Economy Ministry'!C102*EcEnabled+'Environment Ministry'!C102*EnvEnabled+'Defence Ministry'!C102*DefEnabled+'Education Ministry'!C102*EduEnabled+Crises!C102+'Breaking News'!C102+Dilemmas!C102+Startups!C102 -> 25 | D102: =$B102+'Economy Ministry'!D102*EcEnabled+'Environment Ministry'!D102*EnvEnabled+'Defence Ministry'!D102*DefEnabled+'Education Ministry'!D102*EduEnabled+Crises!D102+'Breaking News'!D102+Dilemmas!D102+Startups!D102 -> 25 | E102: =$B102+'Economy Ministry'!E102*EcEnabled+'Environment Ministry'!E102*EnvEnabled+'Defence Ministry'!E102*DefEnabled+'Education Ministry'!E102*EduEnabled+Crises!E102+'Breaking News'!E102+Dilemmas!E102+Startups!E102 -> 25 | F102: =$B102+'Economy Ministry'!F102*EcEnabled+'Environment Ministry'!F102*EnvEnabled+'Defence Ministry'!F102*DefEnabled+'Education Ministry'!F102*EduEnabled+Crises!F102+'Breaking News'!F102+Dilemmas!F102+Startups!F102 -> 24.2 | G102: =$B102+'Economy Ministry'!G102*EcEnabled+'Environment Ministry'!G102*EnvEnabled+'Defence Ministry'!G102*DefEnabled+'Education Ministry'!G102*EduEnabled+Crises!G102+'Breaking News'!G102+Dilemmas!G102+Startups!G102 -> 24.2 | H102: =$B102+'Economy Ministry'!H102*EcEnabled+'Environment Ministry'!H102*EnvEnabled+'Defence Ministry'!H102*DefEnabled+'Education Ministry'!H102*EduEnabled+Crises!H102+'Breaking News'!H102+Dilemmas!H102+Startups!H102 -> 24.2 | I102: =$B102+'Economy Ministry'!I102*EcEnabled+'Environment Ministry'!I102*EnvEnabled+'Defence Ministry'!I102*DefEnabled+'Education Ministry'!I102*EduEnabled+Crises!I102+'Breaking News'!I102+Dilemmas!I102 -> 24.2 | J102: =$B102+'Economy Ministry'!J102*EcEnabled+'Environment Ministry'!J102*EnvEnabled+'Defence Ministry'!J102*DefEnabled+'Education Ministry'!J102*EduEnabled+Crises!J102+'Breaking News'!J102+Dilemmas!J102 -> 24.2
A103: InnovationIndex | B103: 30 | C103: =$B103+'Economy Ministry'!C103*EcEnabled+'Environment Ministry'!C103*EnvEnabled+'Defence Ministry'!C103*DefEnabled+'Education Ministry'!C103*EduEnabled+Crises!C103+'Breaking News'!C103+Dilemmas!C103+Startups!C103 -> 30 | D103: =$B103+'Economy Ministry'!D103*EcEnabled+'Environment Ministry'!D103*EnvEnabled+'Defence Ministry'!D103*DefEnabled+'Education Ministry'!D103*EduEnabled+Crises!D103+'Breaking News'!D103+Dilemmas!D103+Startups!D103 -> 30 | E103: =$B103+'Economy Ministry'!E103*EcEnabled+'Environment Ministry'!E103*EnvEnabled+'Defence Ministry'!E103*DefEnabled+'Education Ministry'!E103*EduEnabled+Crises!E103+'Breaking News'!E103+Dilemmas!E103+Startups!E103 -> 29.6 | F103: =$B103+'Economy Ministry'!F103*EcEnabled+'Environment Ministry'!F103*EnvEnabled+'Defence Ministry'!F103*DefEnabled+'Education Ministry'!F103*EduEnabled+Crises!F103+'Breaking News'!F103+Dilemmas!F103+Startups!F103 -> 29.6 | G103: =$B103+'Economy Ministry'!G103*EcEnabled+'Environment Ministry'!G103*EnvEnabled+'Defence Ministry'!G103*DefEnabled+'Education Ministry'!G103*EduEnabled+Crises!G103+'Breaking News'!G103+Dilemmas!G103+Startups!G103 -> 29.6 | H103: =$B103+'Economy Ministry'!H103*EcEnabled+'Environment Ministry'!H103*EnvEnabled+'Defence Ministry'!H103*DefEnabled+'Education Ministry'!H103*EduEnabled+Crises!H103+'Breaking News'!H103+Dilemmas!H103+Startups!H103 -> 30.1 | I103: =$B103+'Economy Ministry'!I103*EcEnabled+'Environment Ministry'!I103*EnvEnabled+'Defence Ministry'!I103*DefEnabled+'Education Ministry'!I103*EduEnabled+Crises!I103+'Breaking News'!I103+Dilemmas!I103 -> 30.1 | J103: =$B103+'Economy Ministry'!J103*EcEnabled+'Environment Ministry'!J103*EnvEnabled+'Defence Ministry'!J103*DefEnabled+'Education Ministry'!J103*EduEnabled+Crises!J103+'Breaking News'!J103+Dilemmas!J103 -> 30.1
A104: InstitutionalAdoptionRate | B104: 20 | C104: =$B104+'Economy Ministry'!C104*EcEnabled+'Environment Ministry'!C104*EnvEnabled+'Defence Ministry'!C104*DefEnabled+'Education Ministry'!C104*EduEnabled+Crises!C104+'Breaking News'!C104+Dilemmas!C104+Startups!C104 -> 20 | D104: =$B104+'Economy Ministry'!D104*EcEnabled+'Environment Ministry'!D104*EnvEnabled+'Defence Ministry'!D104*DefEnabled+'Education Ministry'!D104*EduEnabled+Crises!D104+'Breaking News'!D104+Dilemmas!D104+Startups!D104 -> 20 | E104: =$B104+'Economy Ministry'!E104*EcEnabled+'Environment Ministry'!E104*EnvEnabled+'Defence Ministry'!E104*DefEnabled+'Education Ministry'!E104*EduEnabled+Crises!E104+'Breaking News'!E104+Dilemmas!E104+Startups!E104 -> 20 | F104: =$B104+'Economy Ministry'!F104*EcEnabled+'Environment Ministry'!F104*EnvEnabled+'Defence Ministry'!F104*DefEnabled+'Education Ministry'!F104*EduEnabled+Crises!F104+'Breaking News'!F104+Dilemmas!F104+Startups!F104 -> 20 | G104: =$B104+'Economy Ministry'!G104*EcEnabled+'Environment Ministry'!G104*EnvEnabled+'Defence Ministry'!G104*DefEnabled+'Education Ministry'!G104*EduEnabled+Crises!G104+'Breaking News'!G104+Dilemmas!G104+Startups!G104 -> 20 | H104: =$B104+'Economy Ministry'!H104*EcEnabled+'Environment Ministry'!H104*EnvEnabled+'Defence Ministry'!H104*DefEnabled+'Education Ministry'!H104*EduEnabled+Crises!H104+'Breaking News'!H104+Dilemmas!H104+Startups!H104 -> 20 | I104: =$B104+'Economy Ministry'!I104*EcEnabled+'Environment Ministry'!I104*EnvEnabled+'Defence Ministry'!I104*DefEnabled+'Education Ministry'!I104*EduEnabled+Crises!I104+'Breaking News'!I104+Dilemmas!I104 -> 20 | J104: =$B104+'Economy Ministry'!J104*EcEnabled+'Environment Ministry'!J104*EnvEnabled+'Defence Ministry'!J104*DefEnabled+'Education Ministry'!J104*EduEnabled+Crises!J104+'Breaking News'!J104+Dilemmas!J104 -> 20
A105: EducationScore | B105: ='Result Targets'!B105 -> 40.811966 | C105: ='Result Targets'!C105 -> 40.811966 | D105: ='Result Targets'!D105 -> 40.811966 | E105: ='Result Targets'!E105 -> 40.589744 | F105: ='Result Targets'!F105 -> 40.145299 | G105: ='Result Targets'!G105 -> 40.145299 | H105: ='Result Targets'!H105 -> 40.423077 | I105: ='Result Targets'!I105 -> 40.423077 | J105: ='Result Targets'!J105 -> 40.423077
A108: Weighted Governance
...

Sheet Result Targets
B1: 0 | C1: 1 | D1: 2 | E1: 3 | F1: 4 | G1: 5 | H1: 6 | I1: 7 | J1: 8
A2: Targets
A4: Economy
A5: AIContributionToGDPTarget | B5: =IF(FacilSetsTargets=1,'Target Settings'!B4,'Target Settings'!E4) -> 12 | C5: =B5 -> 12 | D5: =C5 -> 12 | E5: =D5 -> 12 | F5: =E5 -> 12 | G5: =F5 -> 12 | H5: =G5 -> 12 | I5: =H5 -> 12 | J5: =I5 -> 12
A6: AIFDIStockTarget | B6: 100000000000 | C6: =B6 -> 100000000000 | D6: =C6 -> 100000000000 | E6: =D6 -> 100000000000 | F6: =E6 -> 100000000000 | G6: =F6 -> 100000000000 | H6: =G6 -> 100000000000 | I6: =H6 -> 100000000000 | J6: =I6 -> 100000000000
A9: NetJobsFromAITarget | B9: =IF(FacilSetsTargets=1,'Target Settings'!B6,'Target Settings'!E6) -> 500000 | C9: =B9 -> 500000 | D9: =C9 -> 500000 | E9: =D9 -> 500000 | F9: =E9 -> 500000 | G9: =F9 -> 500000 | H9: =G9 -> 500000 | I9: =H9 -> 500000 | J9: =I9 -> 500000
A12: Environment
A15: RenewableEnergyFactorTarget | B15: =IF(FacilSetsTargets=1,'Target Settings'!B10,'Target Settings'!E10) -> 40 | C15: =B15 -> 40 | D15: =C15 -> 40 | E15: =D15 -> 40 | F15: =E15 -> 40 | G15: =F15 -> 40 | H15: =G15 -> 40 | I15: =H15 -> 40 | J15: =I15 -> 40
A18: CircularityIndexTarget | B18: =IF(FacilSetsTargets=1,'Target Settings'!B11,'Target Settings'!E11) -> 60 | C18: =B18 -> 60 | D18: =C18 -> 60 | E18: =D18 -> 60 | F18: =E18 -> 60 | G18: =F18 -> 60 | H18: =G18 -> 60 | I18: =H18 -> 60 | J18: =I18 -> 60
A19: EcosystemIntegrityIndexTarget | B19: =IF(FacilSetsTargets=1,'Target Settings'!B12,'Target Settings'!E12) -> 60 | C19: =B19 -> 60 | D19: =C19 -> 60 | E19: =D19 -> 60 | F19: =E19 -> 60 | G19: =F19 -> 60 | H19: =G19 -> 60 | I19: =H19 -> 60 | J19: =I19 -> 60
A22: Defense
A23: CybersecurityIndexTarget | B23: =IF(FacilSetsTargets=1,'Target Settings'!B16,'Target Settings'!E16) -> 65 | C23: =B23 -> 65 | D23: =C23 -> 65 | E23: =D23 -> 65 | F23: =E23 -> 65 | G23: =F23 -> 65 | H23: =G23 -> 65 | I23: =H23 -> 65 | J23: =I23 -> 65
A24: AutonomousSystemsSafteyIndexTarget | B24: =IF(FacilSetsTargets=1,'Target Settings'!B17,'Target Settings'!E17) -> 75 | C24: =B24 -> 75 | D24: =C24 -> 75 | E24: =D24 -> 75 | F24: =E24 -> 75 | G24: =F24 -> 75 | H24: =G24 -> 75 | I24: =H24 -> 75 | J24: =I24 -> 75
A27: MilitaryTechnologyTradeBalanceTarget | B27: =IF(FacilSetsTargets=1,'Target Settings'!B18,'Target Settings'!E18) -> 2000000000 | C27: =B27 -> 2000000000 | D27: =C27 -> 2000000000 | E27: =D27 -> 2000000000 | F27: =E27 -> 2000000000 | G27: =F27 -> 2000000000 | H27: =G27 -> 2000000000 | I27: =H27 -> 2000000000 | J27: =I27 -> 2000000000
A30: Education & Innovation
A31: AILiteracyTarget | B31: =IF(FacilSetsTargets=1,'Target Settings'!B22,'Target Settings'!E22) -> 60 | C31: =B31 -> 60 | D31: =C31 -> 60 | E31: =D31 -> 60 | F31: =E31 -> 60 | G31: =F31 -> 60 | H31: =G31 -> 60 | I31: =H31 -> 60 | J31: =I31 -> 60
A32: InnovationIndexTarget | B32: =IF(FacilSetsTargets=1,'Target Settings'!B23,'Target Settings'!E23) -> 60 | C32: =B32 -> 60 | D32: =C32 -> 60 | E32: =D32 -> 60 | F32: =E32 -> 60 | G32: =F32 -> 60 | H32: =G32 -> 60 | I32: =H32 -> 60 | J32: =I32 -> 60
A33: InstitutionalAdoptionRateTarget | B33: =IF(FacilSetsTargets=1,'Target Settings'!B24,'Target Settings'!E24) -> 65 | C33: =B33 -> 65 | D33: =C33 -> 65 | E33: =D33 -> 65 | F33: =E33 -> 65 | G33: =F33 -> 65 | H33: =G33 -> 65 | I33: =H33 -> 65 | J33: =I33 -> 65
A70: Percentage of Target Achieved %
A72: Economy
A73: AIContributionToGDPPercOfTargetAchieved | B73: =MAX((Results!B73)/('Result Targets'!B5),0) * 100 -> 25 | C73: =MAX((Results!C73)/('Result Targets'!C5),0) * 100 -> 22.333333 | D73: =MAX((Results!D73)/('Result Targets'!D5),0) * 100 -> 22.333333 | E73: =MAX((Results!E73)/('Result Targets'!E5),0) * 100 -> 22.333333 | F73: =MAX((Results!F73)/('Result Targets'!F5),0) * 100 -> 22.333333 | G73: =MAX((Results!G73)/('Result Targets'!G5),0) * 100 -> 22.333333 | H73: =MAX((Results!H73)/('Result Targets'!H5),0) * 100 -> 25.666667 | I73: =MAX((Results!I73)/('Result Targets'!I5),0) * 100 -> 25.666667 | J73: =MAX((Results!J73)/('Result Targets'!J5),0) * 100 -> 25.666667
A74: AIFDIStockPercOfTargetAchieved | B74: =MAX((Results!B74)/('Result Targets'!B6),0)*100 -> 50 | C74: =MAX((Results!C74)/('Result Targets'!C6),0)*100 -> 46.8 | D74: =MAX((Results!D74)/('Result Targets'!D6),0)*100 -> 46.8 | E74: =MAX((Results!E74)/('Result Targets'!E6),0)*100 -> 45.2 | F74: =MAX((Results!F74)/('Result Targets'!F6),0)*100 -> 45.2 | G74: =MAX((Results!G74)/('Result Targets'!G6),0)*100 -> 42 | H74: =MAX((Results!H74)/('Result Targets'!H6),0)*100 -> 42 | I74: =MAX((Results!I74)/('Result Targets'!I6),0)*100 -> 42 | J74: =MAX((Results!J74)/('Result Targets'!J6),0)*100 -> 42
A77: NetJobsFromAIPercOfTargetAchieved | B77: =MAX((Results!B77)/('Result Targets'!B9),0)*100 -> 0 | C77: =MAX((Results!C77)/('Result Targets'!C9),0)*100 -> 0 | D77: =MAX((Results!D77)/('Result Targets'!D9),0)*100 -> 0 | E77: =MAX((Results!E77)/('Result Targets'!E9),0)*100 -> 0 | F77: =MAX((Results!F77)/('Result Targets'!F9),0)*100 -> 0 | G77: =MAX((Results!G77)/('Result Targets'!G9),0)*100 -> 0 | H77: =MAX((Results!H77)/('Result Targets'!H9),0)*100 -> 0 | I77: =MAX((Results!I77)/('Result Targets'!I9),0)*100 -> 0 | J77: =MAX((Results!J77)/('Result Targets'!J9),0)*100 -> 0
A78: EconomyScore | B78: =AVERAGE(MIN(B73,100),MIN(B74,100),MIN(B77,100)) -> 25 | C78: =AVERAGE(MIN(C73,100),MIN(C74,100),MIN(C77,100)) -> 23.044444 | D78: =AVERAGE(MIN(D73,100),MIN(D74,100),MIN(D77,100)) -> 23.044444 | E78: =AVERAGE(MIN(E73,100),MIN(E74,100),MIN(E77,100)) -> 22.511111 | F78: =AVERAGE(MIN(F73,100),MIN(F74,100),MIN(F77,100)) -> 22.511111 | G78: =AVERAGE(MIN(G73,100),MIN(G74,100),MIN(G77,100)) -> 21.444444 | H78: =AVERAGE(MIN(H73,100),MIN(H74,100),MIN(H77,100)) -> 22.555556 | I78: =AVERAGE(MIN(I73,100),MIN(I74,100),MIN(I77,100)) -> 22.555556 | J78: =AVERAGE(MIN(J73,100),MIN(J74,100),MIN(J77,100)) -> 22.555556
A81: Environment
A84: RenewableEnergyFactorPercOfTargetAchieved | B84: =MAX((Results!B84)/('Result Targets'!B15),0) * 100 -> 25 | C84: =MAX((Results!C84)/('Result Targets'!C15),0) * 100 -> 25 | D84: =MAX((Results!D84)/('Result Targets'!D15),0) * 100 -> 25 | E84: =MAX((Results!E84)/('Result Targets'!E15),0) * 100 -> 25 | F84: =MAX((Results!F84)/('Result Targets'!F15),0) * 100 -> 25 | G84: =MAX((Results!G84)/('Result Targets'!G15),0) * 100 -> 25 | H84: =MAX((Results!H84)/('Result Targets'!H15),0) * 100 -> 25 | I84: =MAX((Results!I84)/('Result Targets'!I15),0) * 100 -> 25 | J84: =MAX((Results!J84)/('Result Targets'!J15),0) * 100 -> 25
A87: CircularityIndexPercOfTargetAchieved | B87: =MAX((Results!B87)/('Result Targets'!B18),0) * 100 -> 37.5 | C87: =MAX((Results!C87)/('Result Targets'!C18),0) * 100 -> 37.5 | D87: =MAX((Results!D87)/('Result Targets'!D18),0) * 100 -> 37.5 | E87: =MAX((Results!E87)/('Result Targets'!E18),0) * 100 -> 37.5 | F87: =MAX((Results!F87)/('Result Targets'!F18),0) * 100 -> 37.5 | G87: =MAX((Results!G87)/('Result Targets'!G18),0) * 100 -> 37.5 | H87: =MAX((Results!H87)/('Result Targets'!H18),0) * 100 -> 37.5 | I87: =MAX((Results!I87)/('Result Targets'!I18),0) * 100 -> 37.5 | J87: =MAX((Results!J87)/('Result Targets'!J18),0) * 100 -> 37.5
A88: EcosystemIntegrityIndexPercOfTargetAchieved | B88: =MAX((Results!B88)/('Result Targets'!B19),0) * 100 -> 41.666667 | C88: =MAX((Results!C88)/('Result Targets'!C19),0) * 100 -> 41.666667 | D88: =MAX((Results!D88)/('Result Targets'!D19),0) * 100 -> 41.666667 | E88: =MAX((Results!E88)/('Result Targets'!E19),0) * 100 -> 41.666667 | F88: =MAX((Results!F88)/('Result Targets'!F19),0) * 100 -> 41.666667 | G88: =MAX((Results!G88)/('Result Targets'!G19),0) * 100 -> 41.666667 | H88: =MAX((Results!H88)/('Result Targets'!H19),0) * 100 -> 41.666667 | I88: =MAX((Results!I88)/('Result Targets'!I19),0) * 100 -> 41.666667 | J88: =MAX((Results!J88)/('Result Targets'!J19),0) * 100 -> 41.666667
A90: EnvironmentScore | B90: =AVERAGE(MIN(B84,100),MIN(B87,100),MIN(B88,100)) -> 34.722222 | C90: =AVERAGE(MIN(C84,100),MIN(C87,100),MIN(C88,100)) -> 34.722222 | D90: =AVERAGE(MIN(D84,100),MIN(D87,100),MIN(D88,100)) -> 34.722222 | E90: =AVERAGE(MIN(E84,100),MIN(E87,100),MIN(E88,100)) -> 34.722222 | F90: =AVERAGE(MIN(F84,100),MIN(F87,100),MIN(F88,100)) -> 34.722222 | G90: =AVERAGE(MIN(G84,100),MIN(G87,100),MIN(G88,100)) -> 34.722222 | H90: =AVERAGE(MIN(H84,100),MIN(H87,100),MIN(H88,100)) -> 34.722222 | I90: =AVERAGE(MIN(I84,100),MIN(I87,100),MIN(I88,100)) -> 34.722222 | J90: =AVERAGE(MIN(J84,100),MIN(J87,100),MIN(J88,100)) -> 34.722222
A92: Defense
A93: CybersecurityIndexPercOfTargetAchieved | B93: =MAX((Results!B93)/('Result Targets'!B23),0)*100 -> 53.846154 | C93: =MAX((Results!C93)/('Result Targets'!C23),0)*100 -> 53.846154 | D93: =MAX((Results!D93)/('Result Targets'!D23),0)*100 -> 53.846154 | E93: =MAX((Results!E93)/('Result Targets'!E23),0)*100 -> 53.846154 | F93: =MAX((Results!F93)/('Result Targets'!F23),0)*100 -> 53.846154 | G93: =MAX((Results!G93)/('Result Targets'!G23),0)*100 -> 53.846154 | H93: =MAX((Results!H93)/('Result Targets'!H23),0)*100 -> 53.846154 | I93: =MAX((Results!I93)/('Result Targets'!I23),0)*100 -> 53.846154 | J93: =MAX((Results!J93)/('Result Targets'!J23),0)*100 -> 53.846154
A94: AutonomousSystemsSafteyIndexPercOfTargetAchieved | B94: =MAX((Results!B94)/('Result Targets'!B24),0)*100 -> 53.333333 | C94: =MAX((Results!C94)/('Result Targets'!C24),0)*100 -> 53.333333 | D94: =MAX((Results!D94)/('Result Targets'!D24),0)*100 -> 52.266667 | E94: =MAX((Results!E94)/('Result Targets'!E24),0)*100 -> 52.266667 | F94: =MAX((Results!F94)/('Result Targets'!F24),0)*100 -> 52.266667 | G94: =MAX((Results!G94)/('Result Targets'!G24),0)*100 -> 52.266667 | H94: =MAX((Results!H94)/('Result Targets'!H24),0)*100 -> 52.266667 | I94: =MAX((Results!I94)/('Result Targets'!I24),0)*100 -> 52.266667 | J94: =MAX((Results!J94)/('Result Targets'!J24),0)*100 -> 52.266667
A97: MilitaryTechnologyTradeBalancePercOfTargetAchieved | B97: =MAX((Results!B97)/('Result Targets'!B27),0)*100 -> 0 | C97: =MAX((Results!C97)/('Result Targets'!C27),0)*100 -> 0 | D97: =MAX((Results!D97)/('Result Targets'!D27),0)*100 -> 0 | E97: =MAX((Results!E97)/('Result Targets'!E27),0)*100 -> 0 | F97: =MAX((Results!F97)/('Result Targets'!F27),0)*100 -> 0 | G97: =MAX((Results!G97)/('Result Targets'!G27),0)*100 -> 0 | H97: =MAX((Results!H97)/('Result Targets'!H27),0)*100 -> 0 | I97: =MAX((Results!I97)/('Result Targets'!I27),0)*100 -> 0 | J97: =MAX((Results!J97)/('Result Targets'!J27),0)*100 -> 0
A98: DefenseScore | B98: =AVERAGE(MIN(B93,100),MIN(B94,100),MIN(B97,100)) -> 35.726496 | C98: =AVERAGE(MIN(C93,100),MIN(C94,100),MIN(C97,100)) -> 35.726496 | D98: =AVERAGE(MIN(D93,100),MIN(D94,100),MIN(D97,100)) -> 35.37094 | E98: =AVERAGE(MIN(E93,100),MIN(E94,100),MIN(E97,100)) -> 35.37094 | F98: =AVERAGE(MIN(F93,100),MIN(F94,100),MIN(F97,100)) -> 35.37094 | G98: =AVERAGE(MIN(G93,100),MIN(G94,100),MIN(G97,100)) -> 35.37094 | H98: =AVERAGE(MIN(H93,100),MIN(H94,100),MIN(H97,100)) -> 35.37094 | I98: =AVERAGE(MIN(I93,100),MIN(I94,100),MIN(I97,100)) -> 35.37094 | J98: =AVERAGE(MIN(J93,100),MIN(J94,100),MIN(J97,100)) -> 35.37094
A101: Education & Innovation
A102: AILiteracyPercOfTargetAchieved | B102: =MAX((Results!B102)/('Result Targets'!B31),0)*100 -> 41.666667 | C102: =MAX((Results!C102)/('Result Targets'!C31),0)*100 -> 41.666667 | D102: =MAX((Results!D102)/('Result Targets'!D31),0)*100 -> 41.666667 | E102: =MAX((Results!E102)/('Result Targets'!E31),0)*100 -> 41.666667 | F102: =MAX((Results!F102)/('Result Targets'!F31),0)*100 -> 40.333333 | G102: =MAX((Results!G102)/('Result Targets'!G31),0)*100 -> 40.333333 | H102: =MAX((Results!H102)/('Result Targets'!H31),0)*100 -> 40.333333 | I102: =MAX((Results!I102)/('Result Targets'!I31),0)*100 -> 40.333333 | J102: =MAX((Results!J102)/('Result Targets'!J31),0)*100 -> 40.333333
A103: InnovationIndexPercOfTargetAchieved | B103: =MAX((Results!B103)/('Result Targets'!B32),0)*100 -> 50 | C103: =MAX((Results!C103)/('Result Targets'!C32),0)*100 -> 50 | D103: =MAX((Results!D103)/('Result Targets'!D32),0)*100 -> 50 | E103: =MAX((Results!E103)/('Result Targets'!E32),0)*100 -> 49.333333 | F103: =MAX((Results!F103)/('Result Targets'!F32),0)*100 -> 49.333333 | G103: =MAX((Results!G103)/('Result Targets'!G32),0)*100 -> 49.333333 | H103: =MAX((Results!H103)/('Result Targets'!H32),0)*100 -> 50.166667 | I103: =MAX((Results!I103)/('Result Targets'!I32),0)*100 -> 50.166667 | J103: =MAX((Results!J103)/('Result Targets'!J32),0)*100 -> 50.166667
A104: InstitutionalAdoptionRatePercOfTargetAchieved | B104: =MAX((Results!B104)/('Result Targets'!B33),0)*100 -> 30.769231 | C104: =MAX((Results!C104)/('Result Targets'!C33),0)*100 -> 30.769231 | D104: =MAX((Results!D104)/('Result Targets'!D33),0)*100 -> 30.769231 | E104: =MAX((Results!E104)/('Result Targets'!E33),0)*100 -> 30.769231 | F104: =MAX((Results!F104)/('Result Targets'!F33),0)*100 -> 30.769231 | G104: =MAX((Results!G104)/('Result Targets'!G33),0)*100 -> 30.769231 | H104: =MAX((Results!H104)/('Result Targets'!H33),0)*100 -> 30.769231 | I104: =MAX((Results!I104)/('Result Targets'!I33),0)*100 -> 30.769231 | J104: =MAX((Results!J104)/('Result Targets'!J33),0)*100 -> 30.769231
A105: EducationScore | B105: =AVERAGE(MIN(B102,100),MIN(B103,100),MIN(B104,100)) -> 40.811966 | C105: =AVERAGE(MIN(C102,100),MIN(C103,100),MIN(C104,100)) -> 40.811966 | D105: =AVERAGE(MIN(D102,100),MIN(D103,100),MIN(D104,100)) -> 40.811966 | E105: =AVERAGE(MIN(E102,100),MIN(E103,100),MIN(E104,100)) -> 40.589744 | F105: =AVERAGE(MIN(F102,100),MIN(F103,100),MIN(F104,100)) -> 40.145299 | G105: =AVERAGE(MIN(G102,100),MIN(G103,100),MIN(G104,100)) -> 40.145299 | H105: =AVERAGE(MIN(H102,100),MIN(H103,100),MIN(H104,100)) -> 40.423077 | I105: =AVERAGE(MIN(I102,100),MIN(I103,100),MIN(I104,100)) -> 40.423077 | J105: =AVERAGE(MIN(J102,100),MIN(J103,100),MIN(J104,100)) -> 40.423077
A108: Numbers
...

Sheet KPI Impacts
B1: Policy Impacts | K1: Slider Impacts | S1: Slider Costs
B2: HighNeg | C2: MediumNeg | D2: LowNeg | E2: None | F2: LowPos | G2: MediumPos | H2: HighPos | K2: HighNeg | L2: MediumNeg | M2: LowNeg | N2: None | O2: LowPos | P2: MediumPos | Q2: HighPos | S2: Value | T2: 0 | U2: 1 | V2: 2 | W2: 3
A63: Governance | K63: 0 | L63: 0 | M63: 0 | N63: 0 | O63: 0 | P63: 0 | Q63: 0 | S63: Cost | T63: 0 | U63: 10000000 | V63: 20000000 | W63: 40000000
A64: GrowthWellBeing | B64: =H64*-0.8 -> -2.4 | C64: =G64*-0.8 -> -1.6 | D64: =F64*-0.8 -> -0.8 | E64: 0 | F64: 1 | G64: 2 | H64: 3 | K64: =(Q64*-1)*0.6 -> -0.36 | L64: =(P64*-1)*0.6 -> -0.27 | M64: =(O64*-1)*0.6 -> -0.18 | N64: 0 | O64: 0.3 | P64: 0.45 | Q64: 0.6
